2014-03-16 20:22:42,089 [ERROR] django.request: Internal Server Error: /articles/search/
Traceback (most recent call last):
  File "/usr/local/lib/python2.7/dist-packages/django/core/handlers/base.py", line 114, in get_response
    response = wrapped_callback(request, *callback_args, **callback_kwargs)
  File "/home/gk/django_test/article/views.py", line 109, in search_titles
    logr.debug(srch_text)
NameError: global name 'srch_text' is not defined
2014-03-16 20:22:42,089 [ERROR] django.request: Internal Server Error: /articles/search/
Traceback (most recent call last):
  File "/usr/local/lib/python2.7/dist-packages/django/core/handlers/base.py", line 114, in get_response
    response = wrapped_callback(request, *callback_args, **callback_kwargs)
  File "/home/gk/django_test/article/views.py", line 109, in search_titles
    logr.debug(srch_text)
NameError: global name 'srch_text' is not defined
2014-03-16 20:22:42,402 [ERROR] django.request: Internal Server Error: /articles/search/
Traceback (most recent call last):
  File "/usr/local/lib/python2.7/dist-packages/django/core/handlers/base.py", line 114, in get_response
    response = wrapped_callback(request, *callback_args, **callback_kwargs)
  File "/home/gk/django_test/article/views.py", line 109, in search_titles
    logr.debug(srch_text)
NameError: global name 'srch_text' is not defined
2014-03-16 20:22:42,403 [ERROR] django.request: Internal Server Error: /articles/search/
Traceback (most recent call last):
  File "/usr/local/lib/python2.7/dist-packages/django/core/handlers/base.py", line 114, in get_response
    response = wrapped_callback(request, *callback_args, **callback_kwargs)
  File "/home/gk/django_test/article/views.py", line 109, in search_titles
    logr.debug(srch_text)
NameError: global name 'srch_text' is not defined
2014-03-16 20:22:42,403 [ERROR] django.request: Internal Server Error: /articles/search/
Traceback (most recent call last):
  File "/usr/local/lib/python2.7/dist-packages/django/core/handlers/base.py", line 114, in get_response
    response = wrapped_callback(request, *callback_args, **callback_kwargs)
  File "/home/gk/django_test/article/views.py", line 109, in search_titles
    logr.debug(srch_text)
NameError: global name 'srch_text' is not defined
2014-03-16 20:22:42,474 [ERROR] django.request: Internal Server Error: /articles/search/
Traceback (most recent call last):
  File "/usr/local/lib/python2.7/dist-packages/django/core/handlers/base.py", line 114, in get_response
    response = wrapped_callback(request, *callback_args, **callback_kwargs)
  File "/home/gk/django_test/article/views.py", line 109, in search_titles
    logr.debug(srch_text)
NameError: global name 'srch_text' is not defined
2014-03-16 20:24:26,725 [ERROR] django.request: Internal Server Error: /articles/all
Traceback (most recent call last):
  File "/usr/local/lib/python2.7/dist-packages/django/core/handlers/base.py", line 90, in get_response
    response = middleware_method(request)
  File "/usr/local/lib/python2.7/dist-packages/django/middleware/common.py", line 71, in process_request
    if (not urlresolvers.is_valid_path(request.path_info, urlconf) and
  File "/usr/local/lib/python2.7/dist-packages/django/core/urlresolvers.py", line 573, in is_valid_path
    resolve(path, urlconf)
  File "/usr/local/lib/python2.7/dist-packages/django/core/urlresolvers.py", line 453, in resolve
    return get_resolver(urlconf).resolve(path)
  File "/usr/local/lib/python2.7/dist-packages/django/core/urlresolvers.py", line 318, in resolve
    for pattern in self.url_patterns:
  File "/usr/local/lib/python2.7/dist-packages/django/core/urlresolvers.py", line 346, in url_patterns
    patterns = getattr(self.urlconf_module, "urlpatterns", self.urlconf_module)
  File "/usr/local/lib/python2.7/dist-packages/django/core/urlresolvers.py", line 341, in urlconf_module
    self._urlconf_module = import_module(self.urlconf_name)
  File "/usr/local/lib/python2.7/dist-packages/django/utils/importlib.py", line 40, in import_module
    __import__(name)
  File "/home/gk/django_test/django_test/urls.py", line 2, in <module>
    from article.views import HelloTemplate
  File "/home/gk/django_test/article/views.py", line 110
    logr.debug(srch_text)
   ^
IndentationError: unexpected indent
2014-03-16 20:24:44,995 [ERROR] django.request: Internal Server Error: /articles/search/
Traceback (most recent call last):
  File "/usr/local/lib/python2.7/dist-packages/django/core/handlers/base.py", line 114, in get_response
    response = wrapped_callback(request, *callback_args, **callback_kwargs)
  File "/home/gk/django_test/article/views.py", line 109, in search_titles
    logr.debug(srch_text)
NameError: global name 'srch_text' is not defined
2014-03-16 20:24:45,087 [ERROR] django.request: Internal Server Error: /articles/search/
Traceback (most recent call last):
  File "/usr/local/lib/python2.7/dist-packages/django/core/handlers/base.py", line 114, in get_response
    response = wrapped_callback(request, *callback_args, **callback_kwargs)
  File "/home/gk/django_test/article/views.py", line 109, in search_titles
    logr.debug(srch_text)
NameError: global name 'srch_text' is not defined
2014-03-16 20:24:45,339 [ERROR] django.request: Internal Server Error: /articles/search/
Traceback (most recent call last):
  File "/usr/local/lib/python2.7/dist-packages/django/core/handlers/base.py", line 114, in get_response
    response = wrapped_callback(request, *callback_args, **callback_kwargs)
  File "/home/gk/django_test/article/views.py", line 109, in search_titles
    logr.debug(srch_text)
NameError: global name 'srch_text' is not defined
2014-03-16 20:25:08,478 [ERROR] django.request: Internal Server Error: /articles/search/
Traceback (most recent call last):
  File "/usr/local/lib/python2.7/dist-packages/django/core/handlers/base.py", line 114, in get_response
    response = wrapped_callback(request, *callback_args, **callback_kwargs)
  File "/home/gk/django_test/article/views.py", line 109, in search_titles
    logr.debug(srch_text)
NameError: global name 'srch_text' is not defined
2014-03-16 20:25:08,654 [ERROR] django.request: Internal Server Error: /articles/search/
Traceback (most recent call last):
  File "/usr/local/lib/python2.7/dist-packages/django/core/handlers/base.py", line 114, in get_response
    response = wrapped_callback(request, *callback_args, **callback_kwargs)
  File "/home/gk/django_test/article/views.py", line 109, in search_titles
    logr.debug(srch_text)
NameError: global name 'srch_text' is not defined
2014-03-16 20:25:08,842 [ERROR] django.request: Internal Server Error: /articles/search/
Traceback (most recent call last):
  File "/usr/local/lib/python2.7/dist-packages/django/core/handlers/base.py", line 114, in get_response
    response = wrapped_callback(request, *callback_args, **callback_kwargs)
  File "/home/gk/django_test/article/views.py", line 109, in search_titles
    logr.debug(srch_text)
NameError: global name 'srch_text' is not defined
2014-03-16 20:25:09,442 [ERROR] django.request: Internal Server Error: /articles/search/
Traceback (most recent call last):
  File "/usr/local/lib/python2.7/dist-packages/django/core/handlers/base.py", line 114, in get_response
    response = wrapped_callback(request, *callback_args, **callback_kwargs)
  File "/home/gk/django_test/article/views.py", line 109, in search_titles
    logr.debug(srch_text)
NameError: global name 'srch_text' is not defined
2014-03-16 20:25:09,478 [ERROR] django.request: Internal Server Error: /articles/search/
Traceback (most recent call last):
  File "/usr/local/lib/python2.7/dist-packages/django/core/handlers/base.py", line 114, in get_response
    response = wrapped_callback(request, *callback_args, **callback_kwargs)
  File "/home/gk/django_test/article/views.py", line 109, in search_titles
    logr.debug(srch_text)
NameError: global name 'srch_text' is not defined
2014-03-16 20:25:09,657 [ERROR] django.request: Internal Server Error: /articles/search/
Traceback (most recent call last):
  File "/usr/local/lib/python2.7/dist-packages/django/core/handlers/base.py", line 114, in get_response
    response = wrapped_callback(request, *callback_args, **callback_kwargs)
  File "/home/gk/django_test/article/views.py", line 109, in search_titles
    logr.debug(srch_text)
NameError: global name 'srch_text' is not defined
2014-03-16 20:25:09,924 [ERROR] django.request: Internal Server Error: /articles/search/
Traceback (most recent call last):
  File "/usr/local/lib/python2.7/dist-packages/django/core/handlers/base.py", line 114, in get_response
    response = wrapped_callback(request, *callback_args, **callback_kwargs)
  File "/home/gk/django_test/article/views.py", line 109, in search_titles
    logr.debug(srch_text)
NameError: global name 'srch_text' is not defined
2014-03-16 20:26:12,698 [ERROR] django.request: Internal Server Error: /articles/search/
Traceback (most recent call last):
  File "/usr/local/lib/python2.7/dist-packages/django/core/handlers/base.py", line 114, in get_response
    response = wrapped_callback(request, *callback_args, **callback_kwargs)
  File "/home/gk/django_test/article/views.py", line 110, in search_titles
    articles = Article.objects.filter(title__contains=srch_text)
NameError: global name 'srch_text' is not defined
2014-03-16 20:26:12,723 [ERROR] django.request: Internal Server Error: /articles/search/
Traceback (most recent call last):
  File "/usr/local/lib/python2.7/dist-packages/django/core/handlers/base.py", line 114, in get_response
    response = wrapped_callback(request, *callback_args, **callback_kwargs)
  File "/home/gk/django_test/article/views.py", line 110, in search_titles
    articles = Article.objects.filter(title__contains=srch_text)
NameError: global name 'srch_text' is not defined
2014-03-16 20:26:13,069 [ERROR] django.request: Internal Server Error: /articles/search/
Traceback (most recent call last):
  File "/usr/local/lib/python2.7/dist-packages/django/core/handlers/base.py", line 114, in get_response
    response = wrapped_callback(request, *callback_args, **callback_kwargs)
  File "/home/gk/django_test/article/views.py", line 110, in search_titles
    articles = Article.objects.filter(title__contains=srch_text)
NameError: global name 'srch_text' is not defined
2014-03-16 20:26:13,069 [ERROR] django.request: Internal Server Error: /articles/search/
Traceback (most recent call last):
  File "/usr/local/lib/python2.7/dist-packages/django/core/handlers/base.py", line 114, in get_response
    response = wrapped_callback(request, *callback_args, **callback_kwargs)
  File "/home/gk/django_test/article/views.py", line 110, in search_titles
    articles = Article.objects.filter(title__contains=srch_text)
NameError: global name 'srch_text' is not defined
2014-03-16 20:26:37,688 [ERROR] django.request: Internal Server Error: /articles/search/
Traceback (most recent call last):
  File "/usr/local/lib/python2.7/dist-packages/django/core/handlers/base.py", line 114, in get_response
    response = wrapped_callback(request, *callback_args, **callback_kwargs)
  File "/home/gk/django_test/article/views.py", line 110, in search_titles
    articles = Article.objects.filter(title__contains=srch_text)
NameError: global name 'srch_text' is not defined
2014-03-16 20:26:37,845 [ERROR] django.request: Internal Server Error: /articles/search/
Traceback (most recent call last):
  File "/usr/local/lib/python2.7/dist-packages/django/core/handlers/base.py", line 114, in get_response
    response = wrapped_callback(request, *callback_args, **callback_kwargs)
  File "/home/gk/django_test/article/views.py", line 110, in search_titles
    articles = Article.objects.filter(title__contains=srch_text)
NameError: global name 'srch_text' is not defined
2014-03-16 20:26:38,005 [ERROR] django.request: Internal Server Error: /articles/search/
Traceback (most recent call last):
  File "/usr/local/lib/python2.7/dist-packages/django/core/handlers/base.py", line 114, in get_response
    response = wrapped_callback(request, *callback_args, **callback_kwargs)
  File "/home/gk/django_test/article/views.py", line 110, in search_titles
    articles = Article.objects.filter(title__contains=srch_text)
NameError: global name 'srch_text' is not defined
2014-03-16 20:26:38,362 [ERROR] django.request: Internal Server Error: /articles/search/
Traceback (most recent call last):
  File "/usr/local/lib/python2.7/dist-packages/django/core/handlers/base.py", line 114, in get_response
    response = wrapped_callback(request, *callback_args, **callback_kwargs)
  File "/home/gk/django_test/article/views.py", line 110, in search_titles
    articles = Article.objects.filter(title__contains=srch_text)
NameError: global name 'srch_text' is not defined
2014-03-16 20:26:38,459 [ERROR] django.request: Internal Server Error: /articles/search/
Traceback (most recent call last):
  File "/usr/local/lib/python2.7/dist-packages/django/core/handlers/base.py", line 114, in get_response
    response = wrapped_callback(request, *callback_args, **callback_kwargs)
  File "/home/gk/django_test/article/views.py", line 110, in search_titles
    articles = Article.objects.filter(title__contains=srch_text)
NameError: global name 'srch_text' is not defined
2014-03-16 20:26:38,532 [ERROR] django.request: Internal Server Error: /articles/search/
Traceback (most recent call last):
  File "/usr/local/lib/python2.7/dist-packages/django/core/handlers/base.py", line 114, in get_response
    response = wrapped_callback(request, *callback_args, **callback_kwargs)
  File "/home/gk/django_test/article/views.py", line 110, in search_titles
    articles = Article.objects.filter(title__contains=srch_text)
NameError: global name 'srch_text' is not defined
2014-03-16 20:26:38,790 [ERROR] django.request: Internal Server Error: /articles/search/
Traceback (most recent call last):
  File "/usr/local/lib/python2.7/dist-packages/django/core/handlers/base.py", line 114, in get_response
    response = wrapped_callback(request, *callback_args, **callback_kwargs)
  File "/home/gk/django_test/article/views.py", line 110, in search_titles
    articles = Article.objects.filter(title__contains=srch_text)
NameError: global name 'srch_text' is not defined
2014-03-16 20:26:38,843 [ERROR] django.request: Internal Server Error: /articles/search/
Traceback (most recent call last):
  File "/usr/local/lib/python2.7/dist-packages/django/core/handlers/base.py", line 114, in get_response
    response = wrapped_callback(request, *callback_args, **callback_kwargs)
  File "/home/gk/django_test/article/views.py", line 110, in search_titles
    articles = Article.objects.filter(title__contains=srch_text)
NameError: global name 'srch_text' is not defined
2014-03-17 15:13:51,963 [ERROR] django.request: Internal Server Error: /contact
Traceback (most recent call last):
  File "/usr/local/lib/python2.7/dist-packages/django/core/handlers/base.py", line 90, in get_response
    response = middleware_method(request)
  File "/usr/local/lib/python2.7/dist-packages/django/middleware/common.py", line 71, in process_request
    if (not urlresolvers.is_valid_path(request.path_info, urlconf) and
  File "/usr/local/lib/python2.7/dist-packages/django/core/urlresolvers.py", line 573, in is_valid_path
    resolve(path, urlconf)
  File "/usr/local/lib/python2.7/dist-packages/django/core/urlresolvers.py", line 453, in resolve
    return get_resolver(urlconf).resolve(path)
  File "/usr/local/lib/python2.7/dist-packages/django/core/urlresolvers.py", line 318, in resolve
    for pattern in self.url_patterns:
  File "/usr/local/lib/python2.7/dist-packages/django/core/urlresolvers.py", line 346, in url_patterns
    patterns = getattr(self.urlconf_module, "urlpatterns", self.urlconf_module)
  File "/usr/local/lib/python2.7/dist-packages/django/core/urlresolvers.py", line 341, in urlconf_module
    self._urlconf_module = import_module(self.urlconf_name)
  File "/usr/local/lib/python2.7/dist-packages/django/utils/importlib.py", line 40, in import_module
    __import__(name)
  File "/home/gk/django_test/django_test/urls.py", line 6, in <module>
    from django_test.forms import ContactForm1, ContactForm2, ContactForm3
ImportError: cannot import name ContactForm3
2014-03-17 15:18:34,572 [ERROR] django.request: Internal Server Error: /contact
Traceback (most recent call last):
  File "/usr/local/lib/python2.7/dist-packages/django/core/handlers/base.py", line 90, in get_response
    response = middleware_method(request)
  File "/usr/local/lib/python2.7/dist-packages/django/middleware/common.py", line 71, in process_request
    if (not urlresolvers.is_valid_path(request.path_info, urlconf) and
  File "/usr/local/lib/python2.7/dist-packages/django/core/urlresolvers.py", line 573, in is_valid_path
    resolve(path, urlconf)
  File "/usr/local/lib/python2.7/dist-packages/django/core/urlresolvers.py", line 453, in resolve
    return get_resolver(urlconf).resolve(path)
  File "/usr/local/lib/python2.7/dist-packages/django/core/urlresolvers.py", line 318, in resolve
    for pattern in self.url_patterns:
  File "/usr/local/lib/python2.7/dist-packages/django/core/urlresolvers.py", line 346, in url_patterns
    patterns = getattr(self.urlconf_module, "urlpatterns", self.urlconf_module)
  File "/usr/local/lib/python2.7/dist-packages/django/core/urlresolvers.py", line 341, in urlconf_module
    self._urlconf_module = import_module(self.urlconf_name)
  File "/usr/local/lib/python2.7/dist-packages/django/utils/importlib.py", line 40, in import_module
    __import__(name)
  File "/home/gk/django_test/django_test/urls.py", line 6, in <module>
    from django_test.forms import ContactForm3, ContactForm2, ContactForm1
ImportError: cannot import name ContactForm3
2014-03-17 15:19:33,286 [ERROR] django.request: Internal Server Error: /contact
Traceback (most recent call last):
  File "/usr/local/lib/python2.7/dist-packages/django/core/handlers/base.py", line 90, in get_response
    response = middleware_method(request)
  File "/usr/local/lib/python2.7/dist-packages/django/middleware/common.py", line 71, in process_request
    if (not urlresolvers.is_valid_path(request.path_info, urlconf) and
  File "/usr/local/lib/python2.7/dist-packages/django/core/urlresolvers.py", line 573, in is_valid_path
    resolve(path, urlconf)
  File "/usr/local/lib/python2.7/dist-packages/django/core/urlresolvers.py", line 453, in resolve
    return get_resolver(urlconf).resolve(path)
  File "/usr/local/lib/python2.7/dist-packages/django/core/urlresolvers.py", line 318, in resolve
    for pattern in self.url_patterns:
  File "/usr/local/lib/python2.7/dist-packages/django/core/urlresolvers.py", line 346, in url_patterns
    patterns = getattr(self.urlconf_module, "urlpatterns", self.urlconf_module)
  File "/usr/local/lib/python2.7/dist-packages/django/core/urlresolvers.py", line 341, in urlconf_module
    self._urlconf_module = import_module(self.urlconf_name)
  File "/usr/local/lib/python2.7/dist-packages/django/utils/importlib.py", line 40, in import_module
    __import__(name)
  File "/home/gk/django_test/django_test/urls.py", line 6, in <module>
    from django_test.forms import ContactForm3, ContactForm2, ContactForm1
ImportError: cannot import name ContactForm3
2014-03-17 15:20:21,853 [ERROR] django.request: Internal Server Error: /contact
Traceback (most recent call last):
  File "/usr/local/lib/python2.7/dist-packages/django/core/handlers/base.py", line 90, in get_response
    response = middleware_method(request)
  File "/usr/local/lib/python2.7/dist-packages/django/middleware/common.py", line 71, in process_request
    if (not urlresolvers.is_valid_path(request.path_info, urlconf) and
  File "/usr/local/lib/python2.7/dist-packages/django/core/urlresolvers.py", line 573, in is_valid_path
    resolve(path, urlconf)
  File "/usr/local/lib/python2.7/dist-packages/django/core/urlresolvers.py", line 453, in resolve
    return get_resolver(urlconf).resolve(path)
  File "/usr/local/lib/python2.7/dist-packages/django/core/urlresolvers.py", line 318, in resolve
    for pattern in self.url_patterns:
  File "/usr/local/lib/python2.7/dist-packages/django/core/urlresolvers.py", line 346, in url_patterns
    patterns = getattr(self.urlconf_module, "urlpatterns", self.urlconf_module)
  File "/usr/local/lib/python2.7/dist-packages/django/core/urlresolvers.py", line 341, in urlconf_module
    self._urlconf_module = import_module(self.urlconf_name)
  File "/usr/local/lib/python2.7/dist-packages/django/utils/importlib.py", line 40, in import_module
    __import__(name)
  File "/home/gk/django_test/django_test/urls.py", line 27, in <module>
    url(r'^contact/$', ContactWizard.as_view([ContactForm1, ContactForm2, ContactForm3])),
AttributeError: 'function' object has no attribute 'as_view'
2014-03-17 15:23:55,602 [ERROR] django.request: Internal Server Error: /contact
Traceback (most recent call last):
  File "/usr/local/lib/python2.7/dist-packages/django/core/handlers/base.py", line 90, in get_response
    response = middleware_method(request)
  File "/usr/local/lib/python2.7/dist-packages/django/middleware/common.py", line 71, in process_request
    if (not urlresolvers.is_valid_path(request.path_info, urlconf) and
  File "/usr/local/lib/python2.7/dist-packages/django/core/urlresolvers.py", line 573, in is_valid_path
    resolve(path, urlconf)
  File "/usr/local/lib/python2.7/dist-packages/django/core/urlresolvers.py", line 453, in resolve
    return get_resolver(urlconf).resolve(path)
  File "/usr/local/lib/python2.7/dist-packages/django/core/urlresolvers.py", line 318, in resolve
    for pattern in self.url_patterns:
  File "/usr/local/lib/python2.7/dist-packages/django/core/urlresolvers.py", line 346, in url_patterns
    patterns = getattr(self.urlconf_module, "urlpatterns", self.urlconf_module)
  File "/usr/local/lib/python2.7/dist-packages/django/core/urlresolvers.py", line 341, in urlconf_module
    self._urlconf_module = import_module(self.urlconf_name)
  File "/usr/local/lib/python2.7/dist-packages/django/utils/importlib.py", line 40, in import_module
    __import__(name)
  File "/home/gk/django_test/django_test/urls.py", line 27, in <module>
    url(r'^contact/$', ContactWizard.as_view([ContactForm1, ContactForm2, ContactForm3])),
AttributeError: 'function' object has no attribute 'as_view'
2014-03-17 15:31:52,865 [ERROR] django.request: Internal Server Error: /contact
Traceback (most recent call last):
  File "/usr/local/lib/python2.7/dist-packages/django/core/handlers/base.py", line 90, in get_response
    response = middleware_method(request)
  File "/usr/local/lib/python2.7/dist-packages/django/middleware/common.py", line 71, in process_request
    if (not urlresolvers.is_valid_path(request.path_info, urlconf) and
  File "/usr/local/lib/python2.7/dist-packages/django/core/urlresolvers.py", line 573, in is_valid_path
    resolve(path, urlconf)
  File "/usr/local/lib/python2.7/dist-packages/django/core/urlresolvers.py", line 453, in resolve
    return get_resolver(urlconf).resolve(path)
  File "/usr/local/lib/python2.7/dist-packages/django/core/urlresolvers.py", line 318, in resolve
    for pattern in self.url_patterns:
  File "/usr/local/lib/python2.7/dist-packages/django/core/urlresolvers.py", line 346, in url_patterns
    patterns = getattr(self.urlconf_module, "urlpatterns", self.urlconf_module)
  File "/usr/local/lib/python2.7/dist-packages/django/core/urlresolvers.py", line 341, in urlconf_module
    self._urlconf_module = import_module(self.urlconf_name)
  File "/usr/local/lib/python2.7/dist-packages/django/utils/importlib.py", line 40, in import_module
    __import__(name)
  File "/home/gk/django_test/django_test/urls.py", line 9, in <module>
    class ContactWizard(WizardView):
NameError: name 'WizardView' is not defined
2014-03-17 15:33:00,909 [ERROR] django.request: Internal Server Error: /contact
Traceback (most recent call last):
  File "/usr/local/lib/python2.7/dist-packages/django/core/handlers/base.py", line 90, in get_response
    response = middleware_method(request)
  File "/usr/local/lib/python2.7/dist-packages/django/middleware/common.py", line 71, in process_request
    if (not urlresolvers.is_valid_path(request.path_info, urlconf) and
  File "/usr/local/lib/python2.7/dist-packages/django/core/urlresolvers.py", line 573, in is_valid_path
    resolve(path, urlconf)
  File "/usr/local/lib/python2.7/dist-packages/django/core/urlresolvers.py", line 453, in resolve
    return get_resolver(urlconf).resolve(path)
  File "/usr/local/lib/python2.7/dist-packages/django/core/urlresolvers.py", line 318, in resolve
    for pattern in self.url_patterns:
  File "/usr/local/lib/python2.7/dist-packages/django/core/urlresolvers.py", line 346, in url_patterns
    patterns = getattr(self.urlconf_module, "urlpatterns", self.urlconf_module)
  File "/usr/local/lib/python2.7/dist-packages/django/core/urlresolvers.py", line 341, in urlconf_module
    self._urlconf_module = import_module(self.urlconf_name)
  File "/usr/local/lib/python2.7/dist-packages/django/utils/importlib.py", line 40, in import_module
    __import__(name)
  File "/home/gk/django_test/django_test/urls.py", line 27, in <module>
    url(r'^contact/$', ContactWizard.as_view()),
AttributeError: 'function' object has no attribute 'as_view'
2014-03-17 15:40:34,016 [ERROR] django.request: Internal Server Error: /contact
Traceback (most recent call last):
  File "/usr/local/lib/python2.7/dist-packages/django/core/handlers/base.py", line 90, in get_response
    response = middleware_method(request)
  File "/usr/local/lib/python2.7/dist-packages/django/middleware/common.py", line 71, in process_request
    if (not urlresolvers.is_valid_path(request.path_info, urlconf) and
  File "/usr/local/lib/python2.7/dist-packages/django/core/urlresolvers.py", line 573, in is_valid_path
    resolve(path, urlconf)
  File "/usr/local/lib/python2.7/dist-packages/django/core/urlresolvers.py", line 453, in resolve
    return get_resolver(urlconf).resolve(path)
  File "/usr/local/lib/python2.7/dist-packages/django/core/urlresolvers.py", line 318, in resolve
    for pattern in self.url_patterns:
  File "/usr/local/lib/python2.7/dist-packages/django/core/urlresolvers.py", line 346, in url_patterns
    patterns = getattr(self.urlconf_module, "urlpatterns", self.urlconf_module)
  File "/usr/local/lib/python2.7/dist-packages/django/core/urlresolvers.py", line 341, in urlconf_module
    self._urlconf_module = import_module(self.urlconf_name)
  File "/usr/local/lib/python2.7/dist-packages/django/utils/importlib.py", line 40, in import_module
    __import__(name)
  File "/home/gk/django_test/django_test/urls.py", line 14
    wiz = ContactWizard.as_view([ContactForm1, ContactForm2], initial_dict=initial)
      ^
SyntaxError: invalid syntax
2014-03-17 15:41:37,496 [ERROR] django.request: Internal Server Error: /contact
Traceback (most recent call last):
  File "/usr/local/lib/python2.7/dist-packages/django/core/handlers/base.py", line 90, in get_response
    response = middleware_method(request)
  File "/usr/local/lib/python2.7/dist-packages/django/middleware/common.py", line 71, in process_request
    if (not urlresolvers.is_valid_path(request.path_info, urlconf) and
  File "/usr/local/lib/python2.7/dist-packages/django/core/urlresolvers.py", line 573, in is_valid_path
    resolve(path, urlconf)
  File "/usr/local/lib/python2.7/dist-packages/django/core/urlresolvers.py", line 453, in resolve
    return get_resolver(urlconf).resolve(path)
  File "/usr/local/lib/python2.7/dist-packages/django/core/urlresolvers.py", line 318, in resolve
    for pattern in self.url_patterns:
  File "/usr/local/lib/python2.7/dist-packages/django/core/urlresolvers.py", line 346, in url_patterns
    patterns = getattr(self.urlconf_module, "urlpatterns", self.urlconf_module)
  File "/usr/local/lib/python2.7/dist-packages/django/core/urlresolvers.py", line 341, in urlconf_module
    self._urlconf_module = import_module(self.urlconf_name)
  File "/usr/local/lib/python2.7/dist-packages/django/utils/importlib.py", line 40, in import_module
    __import__(name)
  File "/home/gk/django_test/django_test/urls.py", line 14
    wiz = ContactWizard.as_view([ContactForm1, ContactForm2], initial_dict=initial)(request)
      ^
SyntaxError: invalid syntax
2014-03-17 15:41:55,463 [ERROR] django.request: Internal Server Error: /contact
Traceback (most recent call last):
  File "/usr/local/lib/python2.7/dist-packages/django/core/handlers/base.py", line 90, in get_response
    response = middleware_method(request)
  File "/usr/local/lib/python2.7/dist-packages/django/middleware/common.py", line 71, in process_request
    if (not urlresolvers.is_valid_path(request.path_info, urlconf) and
  File "/usr/local/lib/python2.7/dist-packages/django/core/urlresolvers.py", line 573, in is_valid_path
    resolve(path, urlconf)
  File "/usr/local/lib/python2.7/dist-packages/django/core/urlresolvers.py", line 453, in resolve
    return get_resolver(urlconf).resolve(path)
  File "/usr/local/lib/python2.7/dist-packages/django/core/urlresolvers.py", line 318, in resolve
    for pattern in self.url_patterns:
  File "/usr/local/lib/python2.7/dist-packages/django/core/urlresolvers.py", line 346, in url_patterns
    patterns = getattr(self.urlconf_module, "urlpatterns", self.urlconf_module)
  File "/usr/local/lib/python2.7/dist-packages/django/core/urlresolvers.py", line 341, in urlconf_module
    self._urlconf_module = import_module(self.urlconf_name)
  File "/usr/local/lib/python2.7/dist-packages/django/utils/importlib.py", line 40, in import_module
    __import__(name)
  File "/home/gk/django_test/django_test/urls.py", line 44
    
   ^
SyntaxError: invalid syntax
2014-03-17 15:43:18,038 [ERROR] django.request: Internal Server Error: /contact
Traceback (most recent call last):
  File "/usr/local/lib/python2.7/dist-packages/django/core/handlers/base.py", line 90, in get_response
    response = middleware_method(request)
  File "/usr/local/lib/python2.7/dist-packages/django/middleware/common.py", line 71, in process_request
    if (not urlresolvers.is_valid_path(request.path_info, urlconf) and
  File "/usr/local/lib/python2.7/dist-packages/django/core/urlresolvers.py", line 573, in is_valid_path
    resolve(path, urlconf)
  File "/usr/local/lib/python2.7/dist-packages/django/core/urlresolvers.py", line 453, in resolve
    return get_resolver(urlconf).resolve(path)
  File "/usr/local/lib/python2.7/dist-packages/django/core/urlresolvers.py", line 318, in resolve
    for pattern in self.url_patterns:
  File "/usr/local/lib/python2.7/dist-packages/django/core/urlresolvers.py", line 346, in url_patterns
    patterns = getattr(self.urlconf_module, "urlpatterns", self.urlconf_module)
  File "/usr/local/lib/python2.7/dist-packages/django/core/urlresolvers.py", line 341, in urlconf_module
    self._urlconf_module = import_module(self.urlconf_name)
  File "/usr/local/lib/python2.7/dist-packages/django/utils/importlib.py", line 40, in import_module
    __import__(name)
  File "/home/gk/django_test/django_test/urls.py", line 16, in <module>
    wiz = ContactWizard.as_view([ContactForm1, ContactForm2], initial_dict=initial)
AttributeError: 'function' object has no attribute 'as_view'
2014-03-17 15:50:29,466 [ERROR] django.request: Internal Server Error: /contact
Traceback (most recent call last):
  File "/usr/local/lib/python2.7/dist-packages/django/core/handlers/base.py", line 90, in get_response
    response = middleware_method(request)
  File "/usr/local/lib/python2.7/dist-packages/django/middleware/common.py", line 71, in process_request
    if (not urlresolvers.is_valid_path(request.path_info, urlconf) and
  File "/usr/local/lib/python2.7/dist-packages/django/core/urlresolvers.py", line 573, in is_valid_path
    resolve(path, urlconf)
  File "/usr/local/lib/python2.7/dist-packages/django/core/urlresolvers.py", line 453, in resolve
    return get_resolver(urlconf).resolve(path)
  File "/usr/local/lib/python2.7/dist-packages/django/core/urlresolvers.py", line 318, in resolve
    for pattern in self.url_patterns:
  File "/usr/local/lib/python2.7/dist-packages/django/core/urlresolvers.py", line 346, in url_patterns
    patterns = getattr(self.urlconf_module, "urlpatterns", self.urlconf_module)
  File "/usr/local/lib/python2.7/dist-packages/django/core/urlresolvers.py", line 341, in urlconf_module
    self._urlconf_module = import_module(self.urlconf_name)
  File "/usr/local/lib/python2.7/dist-packages/django/utils/importlib.py", line 40, in import_module
    __import__(name)
  File "/home/gk/django_test/django_test/urls.py", line 27, in <module>
    (r'^contact/$', ContactWizard.as_view([ContactForm1, ContactForm2])),
AttributeError: 'function' object has no attribute 'as_view'
2014-03-17 15:52:46,295 [ERROR] django.request: Internal Server Error: /contact
Traceback (most recent call last):
  File "/usr/local/lib/python2.7/dist-packages/django/core/handlers/base.py", line 90, in get_response
    response = middleware_method(request)
  File "/usr/local/lib/python2.7/dist-packages/django/middleware/common.py", line 71, in process_request
    if (not urlresolvers.is_valid_path(request.path_info, urlconf) and
  File "/usr/local/lib/python2.7/dist-packages/django/core/urlresolvers.py", line 573, in is_valid_path
    resolve(path, urlconf)
  File "/usr/local/lib/python2.7/dist-packages/django/core/urlresolvers.py", line 453, in resolve
    return get_resolver(urlconf).resolve(path)
  File "/usr/local/lib/python2.7/dist-packages/django/core/urlresolvers.py", line 318, in resolve
    for pattern in self.url_patterns:
  File "/usr/local/lib/python2.7/dist-packages/django/core/urlresolvers.py", line 346, in url_patterns
    patterns = getattr(self.urlconf_module, "urlpatterns", self.urlconf_module)
  File "/usr/local/lib/python2.7/dist-packages/django/core/urlresolvers.py", line 341, in urlconf_module
    self._urlconf_module = import_module(self.urlconf_name)
  File "/usr/local/lib/python2.7/dist-packages/django/utils/importlib.py", line 40, in import_module
    __import__(name)
  File "/home/gk/django_test/django_test/urls.py", line 27, in <module>
    url(r'^contact/$', ContactWizard.as_view([ContactForm1, ContactForm2])),
AttributeError: 'function' object has no attribute 'as_view'
2014-03-17 16:26:05,549 [ERROR] django.request: Internal Server Error: /contact
Traceback (most recent call last):
  File "/usr/local/lib/python2.7/dist-packages/django/core/handlers/base.py", line 90, in get_response
    response = middleware_method(request)
  File "/usr/local/lib/python2.7/dist-packages/django/middleware/common.py", line 71, in process_request
    if (not urlresolvers.is_valid_path(request.path_info, urlconf) and
  File "/usr/local/lib/python2.7/dist-packages/django/core/urlresolvers.py", line 573, in is_valid_path
    resolve(path, urlconf)
  File "/usr/local/lib/python2.7/dist-packages/django/core/urlresolvers.py", line 453, in resolve
    return get_resolver(urlconf).resolve(path)
  File "/usr/local/lib/python2.7/dist-packages/django/core/urlresolvers.py", line 318, in resolve
    for pattern in self.url_patterns:
  File "/usr/local/lib/python2.7/dist-packages/django/core/urlresolvers.py", line 346, in url_patterns
    patterns = getattr(self.urlconf_module, "urlpatterns", self.urlconf_module)
  File "/usr/local/lib/python2.7/dist-packages/django/core/urlresolvers.py", line 341, in urlconf_module
    self._urlconf_module = import_module(self.urlconf_name)
  File "/usr/local/lib/python2.7/dist-packages/django/utils/importlib.py", line 40, in import_module
    __import__(name)
  File "/home/gk/django_test/django_test/urls.py", line 27, in <module>
    url(r'^contact/$', ContactWizard.as_view([ContactForm1, ContactForm2])),
AttributeError: 'function' object has no attribute 'as_view'
2014-03-17 17:11:43,994 [ERROR] django.request: Internal Server Error: /contact/
Traceback (most recent call last):
  File "/usr/local/lib/python2.7/dist-packages/django/core/handlers/base.py", line 114, in get_response
    response = wrapped_callback(request, *callback_args, **callback_kwargs)
  File "/usr/local/lib/python2.7/dist-packages/django/views/generic/base.py", line 69, in view
    return self.dispatch(request, *args, **kwargs)
  File "/usr/local/lib/python2.7/dist-packages/django/contrib/formtools/wizard/views.py", line 236, in dispatch
    response = super(WizardView, self).dispatch(request, *args, **kwargs)
  File "/usr/local/lib/python2.7/dist-packages/django/views/generic/base.py", line 87, in dispatch
    return handler(request, *args, **kwargs)
  File "/usr/local/lib/python2.7/dist-packages/django/contrib/formtools/wizard/views.py", line 297, in post
    return self.render_done(form, **kwargs)
  File "/usr/local/lib/python2.7/dist-packages/django/contrib/formtools/wizard/views.py", line 350, in render_done
    done_response = self.done(final_form_list, **kwargs)
  File "/home/gk/django_test/django_test/views.py", line 67, in done
    logr.debug(form_data[1]['sender'])
  File "/home/gk/django_test/django_test/views.py", line 76, in process_form_data
    
IndexError: list index out of range
2014-03-17 17:12:46,548 [ERROR] django.request: Internal Server Error: /contact/
Traceback (most recent call last):
  File "/usr/local/lib/python2.7/dist-packages/django/core/handlers/base.py", line 114, in get_response
    response = wrapped_callback(request, *callback_args, **callback_kwargs)
  File "/usr/local/lib/python2.7/dist-packages/django/views/generic/base.py", line 69, in view
    return self.dispatch(request, *args, **kwargs)
  File "/usr/local/lib/python2.7/dist-packages/django/contrib/formtools/wizard/views.py", line 236, in dispatch
    response = super(WizardView, self).dispatch(request, *args, **kwargs)
  File "/usr/local/lib/python2.7/dist-packages/django/views/generic/base.py", line 87, in dispatch
    return handler(request, *args, **kwargs)
  File "/usr/local/lib/python2.7/dist-packages/django/contrib/formtools/wizard/views.py", line 297, in post
    return self.render_done(form, **kwargs)
  File "/usr/local/lib/python2.7/dist-packages/django/contrib/formtools/wizard/views.py", line 350, in render_done
    done_response = self.done(final_form_list, **kwargs)
  File "/home/gk/django_test/django_test/views.py", line 67, in done
    logr.debug(form_data[1]['sender'])
  File "/home/gk/django_test/django_test/views.py", line 76, in process_form_data
    class ContactWizard(SessionWizardView):
IndexError: list index out of range
2014-03-17 17:15:50,305 [ERROR] django.request: Internal Server Error: /contact/
Traceback (most recent call last):
  File "/usr/local/lib/python2.7/dist-packages/django/core/handlers/base.py", line 114, in get_response
    response = wrapped_callback(request, *callback_args, **callback_kwargs)
  File "/usr/local/lib/python2.7/dist-packages/django/views/generic/base.py", line 69, in view
    return self.dispatch(request, *args, **kwargs)
  File "/usr/local/lib/python2.7/dist-packages/django/contrib/formtools/wizard/views.py", line 236, in dispatch
    response = super(WizardView, self).dispatch(request, *args, **kwargs)
  File "/usr/local/lib/python2.7/dist-packages/django/views/generic/base.py", line 87, in dispatch
    return handler(request, *args, **kwargs)
  File "/usr/local/lib/python2.7/dist-packages/django/contrib/formtools/wizard/views.py", line 297, in post
    return self.render_done(form, **kwargs)
  File "/usr/local/lib/python2.7/dist-packages/django/contrib/formtools/wizard/views.py", line 350, in render_done
    done_response = self.done(final_form_list, **kwargs)
  File "/home/gk/django_test/django_test/views.py", line 80, in done
    form_data = process_form_data(form_list)
  File "/home/gk/django_test/django_test/views.py", line 72, in process_form_data
    ['gk@luminoso.com'], fail_silently=False)
  File "/usr/local/lib/python2.7/dist-packages/django/core/mail/__init__.py", line 50, in send_mail
    connection=connection).send()
  File "/usr/local/lib/python2.7/dist-packages/django/core/mail/message.py", line 274, in send
    return self.get_connection(fail_silently).send_messages([self])
  File "/usr/local/lib/python2.7/dist-packages/django/core/mail/backends/smtp.py", line 87, in send_messages
    new_conn_created = self.open()
  File "/usr/local/lib/python2.7/dist-packages/django/core/mail/backends/smtp.py", line 48, in open
    local_hostname=DNS_NAME.get_fqdn())
  File "/usr/lib/python2.7/smtplib.py", line 251, in __init__
    (code, msg) = self.connect(host, port)
  File "/usr/lib/python2.7/smtplib.py", line 311, in connect
    self.sock = self._get_socket(host, port, self.timeout)
  File "/usr/lib/python2.7/smtplib.py", line 286, in _get_socket
    return socket.create_connection((host, port), timeout)
  File "/usr/lib/python2.7/socket.py", line 571, in create_connection
    raise err
error: [Errno 111] Connection refused
2014-03-17 17:36:20,170 [ERROR] django.request: Internal Server Error: /
Traceback (most recent call last):
  File "/usr/local/lib/python2.7/dist-packages/django/core/handlers/base.py", line 114, in get_response
    response = wrapped_callback(request, *callback_args, **callback_kwargs)
  File "/home/gk/django_test/django_test/views.py", line 15, in index
    PARENT_DIR = os.path.abspath(os.path.dirname(__file__) + "/../")
NameError: global name 'os' is not defined
2014-03-17 17:41:44,132 [ERROR] django.request: Internal Server Error: /
Traceback (most recent call last):
  File "/usr/local/lib/python2.7/dist-packages/django/core/handlers/base.py", line 114, in get_response
    response = wrapped_callback(request, *callback_args, **callback_kwargs)
  File "/home/gk/django_test/django_test/views.py", line 17, in index
    logr.debug(EMAIL_PW)
NameError: global name 'EMAIL_PW' is not defined
2014-03-17 17:47:58,764 [ERROR] django.request: Internal Server Error: /
Traceback (most recent call last):
  File "/usr/local/lib/python2.7/dist-packages/django/core/handlers/base.py", line 114, in get_response
    response = wrapped_callback(request, *callback_args, **callback_kwargs)
  File "/home/gk/django_test/django_test/views.py", line 17, in index
    logr.debug(MAIL_HOST_PASSWORD)
NameError: global name 'MAIL_HOST_PASSWORD' is not defined
2014-03-17 17:48:13,173 [ERROR] django.request: Internal Server Error: /
Traceback (most recent call last):
  File "/usr/local/lib/python2.7/dist-packages/django/core/handlers/base.py", line 114, in get_response
    response = wrapped_callback(request, *callback_args, **callback_kwargs)
  File "/home/gk/django_test/django_test/views.py", line 17, in index
    logr.debug(EMAIL_HOST_PASSWORD)
NameError: global name 'EMAIL_HOST_PASSWORD' is not defined
2014-03-17 17:48:48,473 [ERROR] django.request: Internal Server Error: /
Traceback (most recent call last):
  File "/usr/local/lib/python2.7/dist-packages/django/core/handlers/base.py", line 114, in get_response
    response = wrapped_callback(request, *callback_args, **callback_kwargs)
  File "/home/gk/django_test/django_test/views.py", line 17, in index
    logr.debug(EMAIL_HOST_PASSWORD)
NameError: global name 'EMAIL_HOST_PASSWORD' is not defined
2014-03-17 17:51:23,547 [ERROR] django.request: Internal Server Error: /
Traceback (most recent call last):
  File "/usr/local/lib/python2.7/dist-packages/django/core/handlers/base.py", line 114, in get_response
    response = wrapped_callback(request, *callback_args, **callback_kwargs)
  File "/home/gk/django_test/django_test/views.py", line 19, in index
    logr.debug(EMAIL_HOST_PASSWORD)
NameError: global name 'EMAIL_HOST_PASSWORD' is not defined
2014-03-17 17:52:52,950 [ERROR] django.request: Internal Server Error: /contact/
Traceback (most recent call last):
  File "/usr/local/lib/python2.7/dist-packages/django/core/handlers/base.py", line 114, in get_response
    response = wrapped_callback(request, *callback_args, **callback_kwargs)
  File "/usr/local/lib/python2.7/dist-packages/django/views/generic/base.py", line 69, in view
    return self.dispatch(request, *args, **kwargs)
  File "/usr/local/lib/python2.7/dist-packages/django/contrib/formtools/wizard/views.py", line 236, in dispatch
    response = super(WizardView, self).dispatch(request, *args, **kwargs)
  File "/usr/local/lib/python2.7/dist-packages/django/views/generic/base.py", line 87, in dispatch
    return handler(request, *args, **kwargs)
  File "/usr/local/lib/python2.7/dist-packages/django/contrib/formtools/wizard/views.py", line 297, in post
    return self.render_done(form, **kwargs)
  File "/usr/local/lib/python2.7/dist-packages/django/contrib/formtools/wizard/views.py", line 350, in render_done
    done_response = self.done(final_form_list, **kwargs)
  File "/home/gk/django_test/django_test/views.py", line 88, in done
  File "/usr/local/lib/python2.7/dist-packages/django/shortcuts/__init__.py", line 29, in render_to_response
    return HttpResponse(loader.render_to_string(*args, **kwargs), **httpresponse_kwargs)
  File "/usr/local/lib/python2.7/dist-packages/django/template/loader.py", line 162, in render_to_string
    t = get_template(template_name)
  File "/usr/local/lib/python2.7/dist-packages/django/template/loader.py", line 138, in get_template
    template, origin = find_template(template_name)
  File "/usr/local/lib/python2.7/dist-packages/django/template/loader.py", line 127, in find_template
    source, display_name = loader(name, dirs)
  File "/usr/local/lib/python2.7/dist-packages/django/template/loader.py", line 43, in __call__
    return self.load_template(template_name, template_dirs)
  File "/usr/local/lib/python2.7/dist-packages/django/template/loader.py", line 49, in load_template
    template = get_template_from_string(source, origin, template_name)
  File "/usr/local/lib/python2.7/dist-packages/django/template/loader.py", line 149, in get_template_from_string
    return Template(source, origin, name)
  File "/usr/local/lib/python2.7/dist-packages/django/template/base.py", line 125, in __init__
    self.nodelist = compile_string(template_string, origin)
  File "/usr/local/lib/python2.7/dist-packages/django/template/base.py", line 153, in compile_string
    return parser.parse()
  File "/usr/local/lib/python2.7/dist-packages/django/template/base.py", line 276, in parse
    self.invalid_block_tag(token, command, parse_until)
  File "/usr/local/lib/python2.7/dist-packages/django/template/base.py", line 332, in invalid_block_tag
    raise self.error(token, "Invalid block tag: '%s'" % command)
TemplateSyntaxError: Invalid block tag: 'extands'
2014-03-17 21:39:28,066 [ERROR] django.request: Internal Server Error: /articles/all/
Traceback (most recent call last):
  File "/usr/local/lib/python2.7/dist-packages/django/core/handlers/base.py", line 101, in get_response
    resolver_match = resolver.resolve(request.path_info)
  File "/usr/local/lib/python2.7/dist-packages/django/core/urlresolvers.py", line 318, in resolve
    for pattern in self.url_patterns:
  File "/usr/local/lib/python2.7/dist-packages/django/core/urlresolvers.py", line 346, in url_patterns
    patterns = getattr(self.urlconf_module, "urlpatterns", self.urlconf_module)
  File "/usr/local/lib/python2.7/dist-packages/django/core/urlresolvers.py", line 341, in urlconf_module
    self._urlconf_module = import_module(self.urlconf_name)
  File "/usr/local/lib/python2.7/dist-packages/django/utils/importlib.py", line 40, in import_module
    __import__(name)
  File "/home/gk/django_test/django_test/urls.py", line 16, in <module>
    (r'^accounts/', include('userprofile.urls')),
  File "/usr/local/lib/python2.7/dist-packages/django/conf/urls/__init__.py", line 26, in include
    urlconf_module = import_module(urlconf_module)
  File "/usr/local/lib/python2.7/dist-packages/django/utils/importlib.py", line 40, in import_module
    __import__(name)
  File "/home/gk/django_test/userprofile/urls.py", line 4
    url(r'^profile/$', 'userprofile'.views.user_profile'),
                                                         ^
SyntaxError: EOL while scanning string literal
2014-03-17 21:40:13,541 [ERROR] django.request: Internal Server Error: /accounts/profile
Traceback (most recent call last):
  File "/usr/local/lib/python2.7/dist-packages/django/core/handlers/base.py", line 90, in get_response
    response = middleware_method(request)
  File "/usr/local/lib/python2.7/dist-packages/django/middleware/common.py", line 72, in process_request
    urlresolvers.is_valid_path("%s/" % request.path_info, urlconf)):
  File "/usr/local/lib/python2.7/dist-packages/django/core/urlresolvers.py", line 573, in is_valid_path
    resolve(path, urlconf)
  File "/usr/local/lib/python2.7/dist-packages/django/core/urlresolvers.py", line 453, in resolve
    return get_resolver(urlconf).resolve(path)
  File "/usr/local/lib/python2.7/dist-packages/django/core/urlresolvers.py", line 320, in resolve
    sub_match = pattern.resolve(new_path)
  File "/usr/local/lib/python2.7/dist-packages/django/core/urlresolvers.py", line 320, in resolve
    sub_match = pattern.resolve(new_path)
  File "/usr/local/lib/python2.7/dist-packages/django/core/urlresolvers.py", line 222, in resolve
    return ResolverMatch(self.callback, args, kwargs, self.name)
  File "/usr/local/lib/python2.7/dist-packages/django/core/urlresolvers.py", line 229, in callback
    self._callback = get_callable(self._callback_str)
  File "/usr/local/lib/python2.7/dist-packages/django/utils/functional.py", line 32, in wrapper
    result = func(*args)
  File "/usr/local/lib/python2.7/dist-packages/django/core/urlresolvers.py", line 96, in get_callable
    mod = import_module(mod_name)
  File "/usr/local/lib/python2.7/dist-packages/django/utils/importlib.py", line 40, in import_module
    __import__(name)
  File "/home/gk/django_test/userprofile/views.py", line 11
    if form.is.valid():
             ^
SyntaxError: invalid syntax
2014-03-17 21:41:05,744 [ERROR] django.request: Internal Server Error: /accounts/profile/
Traceback (most recent call last):
  File "/usr/local/lib/python2.7/dist-packages/django/core/handlers/base.py", line 114, in get_response
    response = wrapped_callback(request, *callback_args, **callback_kwargs)
  File "/usr/local/lib/python2.7/dist-packages/django/contrib/auth/decorators.py", line 22, in _wrapped_view
    return view_func(request, *args, **kwargs)
  File "/home/gk/django_test/userprofile/views.py", line 17, in user_profile
    profile = user.profile
  File "/usr/local/lib/python2.7/dist-packages/django/utils/functional.py", line 214, in inner
    return func(self._wrapped, *args)
  File "/home/gk/django_test/userprofile/models.py", line 10, in <lambda>
    User.profile = property(lambda u: UserProfile.objects.get_or_create(user=u)[0])
  File "/usr/local/lib/python2.7/dist-packages/django/db/models/manager.py", line 154, in get_or_create
    return self.get_queryset().get_or_create(**kwargs)
  File "/usr/local/lib/python2.7/dist-packages/django/db/models/query.py", line 388, in get_or_create
    six.reraise(*exc_info)
  File "/usr/local/lib/python2.7/dist-packages/django/db/models/query.py", line 380, in get_or_create
    obj.save(force_insert=True, using=self.db)
  File "/usr/local/lib/python2.7/dist-packages/django/db/models/base.py", line 545, in save
    force_update=force_update, update_fields=update_fields)
  File "/usr/local/lib/python2.7/dist-packages/django/db/models/base.py", line 573, in save_base
    updated = self._save_table(raw, cls, force_insert, force_update, using, update_fields)
  File "/usr/local/lib/python2.7/dist-packages/django/db/models/base.py", line 654, in _save_table
    result = self._do_insert(cls._base_manager, using, fields, update_pk, raw)
  File "/usr/local/lib/python2.7/dist-packages/django/db/models/base.py", line 687, in _do_insert
    using=using, raw=raw)
  File "/usr/local/lib/python2.7/dist-packages/django/db/models/manager.py", line 232, in _insert
    return insert_query(self.model, objs, fields, **kwargs)
  File "/usr/local/lib/python2.7/dist-packages/django/db/models/query.py", line 1511, in insert_query
    return query.get_compiler(using=using).execute_sql(return_id)
  File "/usr/local/lib/python2.7/dist-packages/django/db/models/sql/compiler.py", line 899, in execute_sql
    cursor.execute(sql, params)
  File "/usr/local/lib/python2.7/dist-packages/django/db/backends/util.py", line 69, in execute
    return super(CursorDebugWrapper, self).execute(sql, params)
  File "/usr/local/lib/python2.7/dist-packages/django/db/backends/util.py", line 53, in execute
    return self.cursor.execute(sql, params)
  File "/usr/local/lib/python2.7/dist-packages/django/db/backends/mysql/base.py", line 129, in execute
    six.reraise(utils.IntegrityError, utils.IntegrityError(*tuple(e.args)), sys.exc_info()[2])
  File "/usr/local/lib/python2.7/dist-packages/django/db/backends/mysql/base.py", line 124, in execute
    return self.cursor.execute(query, args)
  File "/usr/lib/python2.7/dist-packages/MySQLdb/cursors.py", line 174, in execute
    self.errorhandler(self, exc, value)
  File "/usr/lib/python2.7/dist-packages/MySQLdb/connections.py", line 36, in defaulterrorhandler
    raise errorclass, errorvalue
IntegrityError: (1048, "Column 'likes_cheese' cannot be null")
2014-03-17 21:42:10,670 [ERROR] django.request: Internal Server Error: /accounts/profile/
Traceback (most recent call last):
  File "/usr/local/lib/python2.7/dist-packages/django/core/handlers/base.py", line 114, in get_response
    response = wrapped_callback(request, *callback_args, **callback_kwargs)
  File "/usr/local/lib/python2.7/dist-packages/django/contrib/auth/decorators.py", line 22, in _wrapped_view
    return view_func(request, *args, **kwargs)
  File "/home/gk/django_test/userprofile/views.py", line 17, in user_profile
    profile = user.profile
  File "/usr/local/lib/python2.7/dist-packages/django/utils/functional.py", line 214, in inner
    return func(self._wrapped, *args)
  File "/home/gk/django_test/userprofile/models.py", line 10, in <lambda>
    User.profile = property(lambda u: UserProfile.objects.get_or_create(user=u)[0])
  File "/usr/local/lib/python2.7/dist-packages/django/db/models/manager.py", line 154, in get_or_create
    return self.get_queryset().get_or_create(**kwargs)
  File "/usr/local/lib/python2.7/dist-packages/django/db/models/query.py", line 388, in get_or_create
    six.reraise(*exc_info)
  File "/usr/local/lib/python2.7/dist-packages/django/db/models/query.py", line 380, in get_or_create
    obj.save(force_insert=True, using=self.db)
  File "/usr/local/lib/python2.7/dist-packages/django/db/models/base.py", line 545, in save
    force_update=force_update, update_fields=update_fields)
  File "/usr/local/lib/python2.7/dist-packages/django/db/models/base.py", line 573, in save_base
    updated = self._save_table(raw, cls, force_insert, force_update, using, update_fields)
  File "/usr/local/lib/python2.7/dist-packages/django/db/models/base.py", line 654, in _save_table
    result = self._do_insert(cls._base_manager, using, fields, update_pk, raw)
  File "/usr/local/lib/python2.7/dist-packages/django/db/models/base.py", line 687, in _do_insert
    using=using, raw=raw)
  File "/usr/local/lib/python2.7/dist-packages/django/db/models/manager.py", line 232, in _insert
    return insert_query(self.model, objs, fields, **kwargs)
  File "/usr/local/lib/python2.7/dist-packages/django/db/models/query.py", line 1511, in insert_query
    return query.get_compiler(using=using).execute_sql(return_id)
  File "/usr/local/lib/python2.7/dist-packages/django/db/models/sql/compiler.py", line 899, in execute_sql
    cursor.execute(sql, params)
  File "/usr/local/lib/python2.7/dist-packages/django/db/backends/util.py", line 69, in execute
    return super(CursorDebugWrapper, self).execute(sql, params)
  File "/usr/local/lib/python2.7/dist-packages/django/db/backends/util.py", line 53, in execute
    return self.cursor.execute(sql, params)
  File "/usr/local/lib/python2.7/dist-packages/django/db/backends/mysql/base.py", line 129, in execute
    six.reraise(utils.IntegrityError, utils.IntegrityError(*tuple(e.args)), sys.exc_info()[2])
  File "/usr/local/lib/python2.7/dist-packages/django/db/backends/mysql/base.py", line 124, in execute
    return self.cursor.execute(query, args)
  File "/usr/lib/python2.7/dist-packages/MySQLdb/cursors.py", line 174, in execute
    self.errorhandler(self, exc, value)
  File "/usr/lib/python2.7/dist-packages/MySQLdb/connections.py", line 36, in defaulterrorhandler
    raise errorclass, errorvalue
IntegrityError: (1048, "Column 'likes_cheese' cannot be null")
2014-04-10 15:00:03,327 [WARNING] django.request: Not Found: /favicon.ico
2014-04-10 17:11:18,138 [WARNING] django.request: Not Found: /index.html
2014-04-10 17:11:18,214 [WARNING] django.request: Not Found: /favicon.ico
2014-04-13 00:53:12,464 [WARNING] django.request: Not Found: /favicon.ico
2014-08-06 00:02:05,477 [WARNING] django.request: Not Found: /favicon.ico
2014-08-07 00:36:34,532 [WARNING] django.request: Not Found: /hello_bootstrap/
2014-08-07 00:37:20,203 [WARNING] django.request: Not Found: /hello_bootstrap
2014-08-07 00:38:43,959 [WARNING] django.request: Not Found: /hello_template/css/bootstrap.min.css
2014-08-07 00:38:43,989 [WARNING] django.request: Not Found: /hello_template/js/bootstrap.min.js
2014-08-07 00:38:58,146 [WARNING] django.request: Not Found: /hello_bootstrap/css/bootstrap.min.css
2014-08-07 00:38:58,555 [WARNING] django.request: Not Found: /hello_bootstrap/js/bootstrap.min.js
2014-08-07 00:39:17,803 [WARNING] django.request: Not Found: /hello_template/css/bootstrap.min.css
2014-08-07 00:39:17,813 [WARNING] django.request: Not Found: /hello_template/js/bootstrap.min.js
2014-08-07 00:39:26,802 [ERROR] django.request: Internal Server Error: /hello_template/
Traceback (most recent call last):
  File "/usr/local/lib/python2.7/dist-packages/django/core/handlers/base.py", line 114, in get_response
    response = wrapped_callback(request, *callback_args, **callback_kwargs)
  File "/home/gk/django_test/article/views.py", line 138, in hello_template
    t = get_template('hello_template.html')
  File "/usr/local/lib/python2.7/dist-packages/django/template/loader.py", line 138, in get_template
    template, origin = find_template(template_name)
  File "/usr/local/lib/python2.7/dist-packages/django/template/loader.py", line 131, in find_template
    raise TemplateDoesNotExist(name)
TemplateDoesNotExist: hello_template.html
2014-08-07 00:40:00,503 [WARNING] django.request: Not Found: /hello_bootstrap/js/bootstrap.min.js
2014-08-07 00:40:00,826 [WARNING] django.request: Not Found: /hello_bootstrap/css/bootstrap.min.css
2014-08-07 00:41:26,758 [WARNING] django.request: Not Found: /dist/css/bootstrap.min.css
2014-08-07 00:41:26,758 [WARNING] django.request: Not Found: /hello_bootstrap/starter-template.css
2014-08-07 00:41:26,766 [WARNING] django.request: Not Found: /assets/js/ie10-viewport-bug-workaround.js
2014-08-07 00:41:26,774 [WARNING] django.request: Not Found: /dist/js/bootstrap.min.js
2014-08-07 00:51:32,436 [WARNING] django.request: Not Found: /hello_bootstrap/starter-template.css
2014-08-07 00:51:32,437 [WARNING] django.request: Not Found: /assets/js/ie10-viewport-bug-workaround.js
2014-08-07 00:51:32,476 [WARNING] django.request: Not Found: /dist/js/bootstrap.min.js
2014-08-07 00:55:48,505 [WARNING] django.request: Not Found: /dist/css/bootstrap.min.css
2014-08-07 00:55:48,514 [WARNING] django.request: Not Found: /assets/js/ie10-viewport-bug-workaround.js
2014-08-07 00:55:48,530 [WARNING] django.request: Not Found: /hello_bootstrap/starter-template.css
2014-08-07 15:29:14,299 [ERROR] django.request: Internal Server Error: /
Traceback (most recent call last):
  File "/usr/local/lib/python2.7/dist-packages/django/core/handlers/base.py", line 114, in get_response
    response = wrapped_callback(request, *callback_args, **callback_kwargs)
  File "/home/gk/django_test/django_test/views.py", line 17, in index
    return render_to_response('index.html', context, context_instance=RequestContext(request))
  File "/usr/local/lib/python2.7/dist-packages/django/shortcuts/__init__.py", line 29, in render_to_response
    return HttpResponse(loader.render_to_string(*args, **kwargs), **httpresponse_kwargs)
  File "/usr/local/lib/python2.7/dist-packages/django/template/loader.py", line 162, in render_to_string
    t = get_template(template_name)
  File "/usr/local/lib/python2.7/dist-packages/django/template/loader.py", line 138, in get_template
    template, origin = find_template(template_name)
  File "/usr/local/lib/python2.7/dist-packages/django/template/loader.py", line 127, in find_template
    source, display_name = loader(name, dirs)
  File "/usr/local/lib/python2.7/dist-packages/django/template/loader.py", line 43, in __call__
    return self.load_template(template_name, template_dirs)
  File "/usr/local/lib/python2.7/dist-packages/django/template/loader.py", line 49, in load_template
    template = get_template_from_string(source, origin, template_name)
  File "/usr/local/lib/python2.7/dist-packages/django/template/loader.py", line 149, in get_template_from_string
    return Template(source, origin, name)
  File "/usr/local/lib/python2.7/dist-packages/django/template/base.py", line 125, in __init__
    self.nodelist = compile_string(template_string, origin)
  File "/usr/local/lib/python2.7/dist-packages/django/template/base.py", line 153, in compile_string
    return parser.parse()
  File "/usr/local/lib/python2.7/dist-packages/django/template/base.py", line 278, in parse
    compiled_result = compile_func(self, token)
  File "/usr/local/lib/python2.7/dist-packages/django/template/loader_tags.py", line 215, in do_extends
    nodelist = parser.parse()
  File "/usr/local/lib/python2.7/dist-packages/django/template/base.py", line 278, in parse
    compiled_result = compile_func(self, token)
  File "/usr/local/lib/python2.7/dist-packages/django/template/loader_tags.py", line 190, in do_block
    nodelist = parser.parse(('endblock',))
  File "/usr/local/lib/python2.7/dist-packages/django/template/base.py", line 276, in parse
    self.invalid_block_tag(token, command, parse_until)
  File "/usr/local/lib/python2.7/dist-packages/django/template/base.py", line 331, in invalid_block_tag
    (command, get_text_list(["'%s'" % p for p in parse_until])))
TemplateSyntaxError: Invalid block tag: 'user.is_authenticated', expected 'endblock'
2014-08-08 01:11:07,479 [ERROR] django.request: Internal Server Error: /hello_template_simple/
Traceback (most recent call last):
  File "/usr/local/lib/python2.7/dist-packages/django/core/handlers/base.py", line 101, in get_response
    resolver_match = resolver.resolve(request.path_info)
  File "/usr/local/lib/python2.7/dist-packages/django/core/urlresolvers.py", line 318, in resolve
    for pattern in self.url_patterns:
  File "/usr/local/lib/python2.7/dist-packages/django/core/urlresolvers.py", line 346, in url_patterns
    patterns = getattr(self.urlconf_module, "urlpatterns", self.urlconf_module)
  File "/usr/local/lib/python2.7/dist-packages/django/core/urlresolvers.py", line 341, in urlconf_module
    self._urlconf_module = import_module(self.urlconf_name)
  File "/usr/local/lib/python2.7/dist-packages/django/utils/importlib.py", line 40, in import_module
    __import__(name)
  File "/home/gk/django_test/django_test/urls.py", line 2, in <module>
    from article.views import HelloTemplate
  File "/home/gk/django_test/article/views.py", line 37
    args['logged_in'] = request.user.is_authenticated()
                                                      ^
IndentationError: unindent does not match any outer indentation level
2014-08-08 01:12:10,171 [ERROR] django.request: Internal Server Error: /hello_template_simple/
Traceback (most recent call last):
  File "/usr/local/lib/python2.7/dist-packages/django/core/handlers/base.py", line 101, in get_response
    resolver_match = resolver.resolve(request.path_info)
  File "/usr/local/lib/python2.7/dist-packages/django/core/urlresolvers.py", line 318, in resolve
    for pattern in self.url_patterns:
  File "/usr/local/lib/python2.7/dist-packages/django/core/urlresolvers.py", line 346, in url_patterns
    patterns = getattr(self.urlconf_module, "urlpatterns", self.urlconf_module)
  File "/usr/local/lib/python2.7/dist-packages/django/core/urlresolvers.py", line 341, in urlconf_module
    self._urlconf_module = import_module(self.urlconf_name)
  File "/usr/local/lib/python2.7/dist-packages/django/utils/importlib.py", line 40, in import_module
    __import__(name)
  File "/home/gk/django_test/django_test/urls.py", line 2, in <module>
    from article.views import HelloTemplate
  File "/home/gk/django_test/article/views.py", line 39
    return render_to_response('articles.html', args)
   ^
IndentationError: unexpected indent
2014-08-08 01:12:11,724 [ERROR] django.request: Internal Server Error: /hello_template_simple/
Traceback (most recent call last):
  File "/usr/local/lib/python2.7/dist-packages/django/core/handlers/base.py", line 101, in get_response
    resolver_match = resolver.resolve(request.path_info)
  File "/usr/local/lib/python2.7/dist-packages/django/core/urlresolvers.py", line 318, in resolve
    for pattern in self.url_patterns:
  File "/usr/local/lib/python2.7/dist-packages/django/core/urlresolvers.py", line 346, in url_patterns
    patterns = getattr(self.urlconf_module, "urlpatterns", self.urlconf_module)
  File "/usr/local/lib/python2.7/dist-packages/django/core/urlresolvers.py", line 341, in urlconf_module
    self._urlconf_module = import_module(self.urlconf_name)
  File "/usr/local/lib/python2.7/dist-packages/django/utils/importlib.py", line 40, in import_module
    __import__(name)
  File "/home/gk/django_test/django_test/urls.py", line 2, in <module>
    from article.views import HelloTemplate
  File "/home/gk/django_test/article/views.py", line 39
    return render_to_response('articles.html', args)
   ^
IndentationError: unexpected indent
2014-08-08 01:12:28,777 [ERROR] django.request: Internal Server Error: /hello_template_simple/
Traceback (most recent call last):
  File "/usr/local/lib/python2.7/dist-packages/django/core/handlers/base.py", line 101, in get_response
    resolver_match = resolver.resolve(request.path_info)
  File "/usr/local/lib/python2.7/dist-packages/django/core/urlresolvers.py", line 318, in resolve
    for pattern in self.url_patterns:
  File "/usr/local/lib/python2.7/dist-packages/django/core/urlresolvers.py", line 346, in url_patterns
    patterns = getattr(self.urlconf_module, "urlpatterns", self.urlconf_module)
  File "/usr/local/lib/python2.7/dist-packages/django/core/urlresolvers.py", line 341, in urlconf_module
    self._urlconf_module = import_module(self.urlconf_name)
  File "/usr/local/lib/python2.7/dist-packages/django/utils/importlib.py", line 40, in import_module
    __import__(name)
  File "/home/gk/django_test/django_test/urls.py", line 2, in <module>
    from article.views import HelloTemplate
  File "/home/gk/django_test/article/views.py", line 45
    return render_to_response('article.html',
                                            ^
IndentationError: unindent does not match any outer indentation level
2014-08-08 01:50:38,246 [WARNING] django.request: Not Found: /accounts/invalid_login/
2014-08-08 01:51:02,652 [WARNING] django.request: Not Found: /invalid_login/
2014-08-08 13:27:15,650 [ERROR] django.request: Internal Server Error: /
Traceback (most recent call last):
  File "/usr/local/lib/python2.7/dist-packages/django/core/handlers/base.py", line 101, in get_response
    resolver_match = resolver.resolve(request.path_info)
  File "/usr/local/lib/python2.7/dist-packages/django/core/urlresolvers.py", line 318, in resolve
    for pattern in self.url_patterns:
  File "/usr/local/lib/python2.7/dist-packages/django/core/urlresolvers.py", line 346, in url_patterns
    patterns = getattr(self.urlconf_module, "urlpatterns", self.urlconf_module)
  File "/usr/local/lib/python2.7/dist-packages/django/core/urlresolvers.py", line 341, in urlconf_module
    self._urlconf_module = import_module(self.urlconf_name)
  File "/usr/local/lib/python2.7/dist-packages/django/utils/importlib.py", line 40, in import_module
    __import__(name)
  File "/home/gk/django_test/django_test/urls.py", line 2, in <module>
    from article.views import HelloTemplate
  File "/home/gk/django_test/article/views.py", line 62
    return HttpResponseRedirect('/articles/all')
   ^
IndentationError: unexpected indent
2014-08-08 13:27:44,781 [ERROR] django.request: Internal Server Error: /
Traceback (most recent call last):
  File "/usr/local/lib/python2.7/dist-packages/django/core/handlers/base.py", line 101, in get_response
    resolver_match = resolver.resolve(request.path_info)
  File "/usr/local/lib/python2.7/dist-packages/django/core/urlresolvers.py", line 318, in resolve
    for pattern in self.url_patterns:
  File "/usr/local/lib/python2.7/dist-packages/django/core/urlresolvers.py", line 346, in url_patterns
    patterns = getattr(self.urlconf_module, "urlpatterns", self.urlconf_module)
  File "/usr/local/lib/python2.7/dist-packages/django/core/urlresolvers.py", line 341, in urlconf_module
    self._urlconf_module = import_module(self.urlconf_name)
  File "/usr/local/lib/python2.7/dist-packages/django/utils/importlib.py", line 40, in import_module
    __import__(name)
  File "/home/gk/django_test/django_test/urls.py", line 2, in <module>
    from article.views import HelloTemplate
  File "/home/gk/django_test/article/views.py", line 62
    return HttpResponseRedirect('/articles/all')
   ^
IndentationError: unexpected indent
2014-08-08 13:28:11,486 [ERROR] django.request: Internal Server Error: /
Traceback (most recent call last):
  File "/usr/local/lib/python2.7/dist-packages/django/core/handlers/base.py", line 101, in get_response
    resolver_match = resolver.resolve(request.path_info)
  File "/usr/local/lib/python2.7/dist-packages/django/core/urlresolvers.py", line 318, in resolve
    for pattern in self.url_patterns:
  File "/usr/local/lib/python2.7/dist-packages/django/core/urlresolvers.py", line 346, in url_patterns
    patterns = getattr(self.urlconf_module, "urlpatterns", self.urlconf_module)
  File "/usr/local/lib/python2.7/dist-packages/django/core/urlresolvers.py", line 341, in urlconf_module
    self._urlconf_module = import_module(self.urlconf_name)
  File "/usr/local/lib/python2.7/dist-packages/django/utils/importlib.py", line 40, in import_module
    __import__(name)
  File "/home/gk/django_test/django_test/urls.py", line 2, in <module>
    from article.views import HelloTemplate
  File "/home/gk/django_test/article/views.py", line 152
    return render_to_response('hello.html', {'name': 'GK'}, context_instance=RequestContext(request))
   ^
IndentationError: unexpected indent
2014-08-08 13:28:24,261 [ERROR] django.request: Internal Server Error: /
Traceback (most recent call last):
  File "/usr/local/lib/python2.7/dist-packages/django/core/handlers/base.py", line 101, in get_response
    resolver_match = resolver.resolve(request.path_info)
  File "/usr/local/lib/python2.7/dist-packages/django/core/urlresolvers.py", line 318, in resolve
    for pattern in self.url_patterns:
  File "/usr/local/lib/python2.7/dist-packages/django/core/urlresolvers.py", line 346, in url_patterns
    patterns = getattr(self.urlconf_module, "urlpatterns", self.urlconf_module)
  File "/usr/local/lib/python2.7/dist-packages/django/core/urlresolvers.py", line 341, in urlconf_module
    self._urlconf_module = import_module(self.urlconf_name)
  File "/usr/local/lib/python2.7/dist-packages/django/utils/importlib.py", line 40, in import_module
    __import__(name)
  File "/home/gk/django_test/django_test/urls.py", line 7, in <module>
    from django_test.views import ContactWizard
  File "/home/gk/django_test/django_test/views.py", line 57
    return render_to_response('register.html', args)
                                                   ^
IndentationError: unindent does not match any outer indentation level
2014-08-08 13:28:41,794 [ERROR] django.request: Internal Server Error: /
Traceback (most recent call last):
  File "/usr/local/lib/python2.7/dist-packages/django/core/handlers/base.py", line 101, in get_response
    resolver_match = resolver.resolve(request.path_info)
  File "/usr/local/lib/python2.7/dist-packages/django/core/urlresolvers.py", line 318, in resolve
    for pattern in self.url_patterns:
  File "/usr/local/lib/python2.7/dist-packages/django/core/urlresolvers.py", line 346, in url_patterns
    patterns = getattr(self.urlconf_module, "urlpatterns", self.urlconf_module)
  File "/usr/local/lib/python2.7/dist-packages/django/core/urlresolvers.py", line 341, in urlconf_module
    self._urlconf_module = import_module(self.urlconf_name)
  File "/usr/local/lib/python2.7/dist-packages/django/utils/importlib.py", line 40, in import_module
    __import__(name)
  File "/home/gk/django_test/django_test/urls.py", line 7, in <module>
    from django_test.views import ContactWizard
  File "/home/gk/django_test/django_test/views.py", line 56
    args['form'] = MyRegistrationForm()
                                      ^
IndentationError: unindent does not match any outer indentation level
2014-08-08 13:29:01,232 [ERROR] django.request: Internal Server Error: /
Traceback (most recent call last):
  File "/usr/local/lib/python2.7/dist-packages/django/core/handlers/base.py", line 101, in get_response
    resolver_match = resolver.resolve(request.path_info)
  File "/usr/local/lib/python2.7/dist-packages/django/core/urlresolvers.py", line 318, in resolve
    for pattern in self.url_patterns:
  File "/usr/local/lib/python2.7/dist-packages/django/core/urlresolvers.py", line 346, in url_patterns
    patterns = getattr(self.urlconf_module, "urlpatterns", self.urlconf_module)
  File "/usr/local/lib/python2.7/dist-packages/django/core/urlresolvers.py", line 341, in urlconf_module
    self._urlconf_module = import_module(self.urlconf_name)
  File "/usr/local/lib/python2.7/dist-packages/django/utils/importlib.py", line 40, in import_module
    __import__(name)
  File "/home/gk/django_test/django_test/urls.py", line 7, in <module>
    from django_test.views import ContactWizard
  File "/home/gk/django_test/django_test/views.py", line 51
    return HttpResponseRedirect('/accounts/register_success')
                                                            ^
IndentationError: unindent does not match any outer indentation level
2014-08-08 13:29:35,039 [ERROR] django.request: Internal Server Error: /accounts/loggedin/
Traceback (most recent call last):
  File "/usr/local/lib/python2.7/dist-packages/django/core/handlers/base.py", line 114, in get_response
    response = wrapped_callback(request, *callback_args, **callback_kwargs)
  File "/home/gk/django_test/django_test/views.py", line 36, in loggedin
    return render_to_response('loggedin.html', args, context_instance=RequestContext(request))
NameError: global name 'args' is not defined
2014-08-08 13:30:31,834 [ERROR] django.request: Internal Server Error: /accounts/loggedin/
Traceback (most recent call last):
  File "/usr/local/lib/python2.7/dist-packages/django/core/handlers/base.py", line 114, in get_response
    response = wrapped_callback(request, *callback_args, **callback_kwargs)
  File "/home/gk/django_test/django_test/views.py", line 36, in loggedin
    return render_to_response('loggedin.html', args, context_instance=RequestContext(request))
NameError: global name 'args' is not defined
2014-08-08 13:30:32,872 [ERROR] django.request: Internal Server Error: /accounts/loggedin/
Traceback (most recent call last):
  File "/usr/local/lib/python2.7/dist-packages/django/core/handlers/base.py", line 114, in get_response
    response = wrapped_callback(request, *callback_args, **callback_kwargs)
  File "/home/gk/django_test/django_test/views.py", line 36, in loggedin
    return render_to_response('loggedin.html', args, context_instance=RequestContext(request))
NameError: global name 'args' is not defined
2014-08-08 13:30:56,761 [ERROR] django.request: Internal Server Error: /accounts/loggedin/
Traceback (most recent call last):
  File "/usr/local/lib/python2.7/dist-packages/django/core/handlers/base.py", line 114, in get_response
    response = wrapped_callback(request, *callback_args, **callback_kwargs)
  File "/home/gk/django_test/django_test/views.py", line 36, in loggedin
    return render_to_response('loggedin.html', args, context_instance=RequestContext(request))
NameError: global name 'args' is not defined
2014-08-08 13:31:40,876 [ERROR] django.request: Internal Server Error: /accounts/loggedin/
Traceback (most recent call last):
  File "/usr/local/lib/python2.7/dist-packages/django/core/handlers/base.py", line 114, in get_response
    response = wrapped_callback(request, *callback_args, **callback_kwargs)
  File "/home/gk/django_test/django_test/views.py", line 36, in loggedin
    return render_to_response('loggedin.html', args, context_instance=RequestContext(request))
NameError: global name 'args' is not defined
2014-08-08 13:32:22,582 [ERROR] django.request: Internal Server Error: /accounts/loggedin/
Traceback (most recent call last):
  File "/usr/local/lib/python2.7/dist-packages/django/core/handlers/base.py", line 114, in get_response
    response = wrapped_callback(request, *callback_args, **callback_kwargs)
  File "/home/gk/django_test/django_test/views.py", line 36, in loggedin
    return render_to_response('loggedin.html', args, context_instance=RequestContext(request))
NameError: global name 'args' is not defined
2014-08-08 13:32:30,372 [ERROR] django.request: Internal Server Error: /accounts/loggedin/
Traceback (most recent call last):
  File "/usr/local/lib/python2.7/dist-packages/django/core/handlers/base.py", line 114, in get_response
    response = wrapped_callback(request, *callback_args, **callback_kwargs)
  File "/home/gk/django_test/django_test/views.py", line 36, in loggedin
    return render_to_response('loggedin.html', args, context_instance=RequestContext(request))
NameError: global name 'args' is not defined
2014-08-08 13:32:34,790 [ERROR] django.request: Internal Server Error: /accounts/loggedin/
Traceback (most recent call last):
  File "/usr/local/lib/python2.7/dist-packages/django/core/handlers/base.py", line 114, in get_response
    response = wrapped_callback(request, *callback_args, **callback_kwargs)
  File "/home/gk/django_test/django_test/views.py", line 36, in loggedin
    return render_to_response('loggedin.html', args, context_instance=RequestContext(request))
NameError: global name 'args' is not defined
2014-08-08 13:33:06,087 [ERROR] django.request: Internal Server Error: /accounts/loggedin/
Traceback (most recent call last):
  File "/usr/local/lib/python2.7/dist-packages/django/core/handlers/base.py", line 114, in get_response
    response = wrapped_callback(request, *callback_args, **callback_kwargs)
  File "/home/gk/django_test/django_test/views.py", line 36, in loggedin
    return render_to_response('loggedin.html', context_instance=RequestContext(request))
NameError: global name 'args' is not defined
2014-08-08 13:34:03,206 [ERROR] django.request: Internal Server Error: /accounts/invalid/
Traceback (most recent call last):
  File "/usr/local/lib/python2.7/dist-packages/django/core/handlers/base.py", line 114, in get_response
    response = wrapped_callback(request, *callback_args, **callback_kwargs)
  File "/home/gk/django_test/django_test/views.py", line 39, in invalid_login
    return render_to_response('invalid_login.html', args, context_instance=RequestContext(request))
NameError: global name 'args' is not defined
2014-08-08 13:37:28,368 [WARNING] django.request: Not Found: /accounts/user_profile/
2014-08-08 13:47:00,704 [WARNING] django.request: Not Found: /user_profile/user_profile/
2014-08-08 13:47:39,678 [WARNING] django.request: Not Found: /user_profile/user_profile/
2014-08-08 13:47:42,251 [WARNING] django.request: Not Found: /user_profile/user_profile/
2014-08-08 13:47:45,780 [WARNING] django.request: Not Found: /profile/
2014-08-08 13:48:06,553 [WARNING] django.request: Not Found: /user_profile/profile/
2014-08-08 14:54:09,748 [ERROR] django.request: Internal Server Error: /accounts/login/
Traceback (most recent call last):
  File "/usr/local/lib/python2.7/dist-packages/django/core/handlers/base.py", line 114, in get_response
    response = wrapped_callback(request, *callback_args, **callback_kwargs)
  File "/home/gk/django_test/django_test/views.py", line 22, in login
    return render_to_response('login.html', c, context_instance=RequestContext(request))
  File "/usr/local/lib/python2.7/dist-packages/django/shortcuts/__init__.py", line 29, in render_to_response
    return HttpResponse(loader.render_to_string(*args, **kwargs), **httpresponse_kwargs)
  File "/usr/local/lib/python2.7/dist-packages/django/template/loader.py", line 162, in render_to_string
    t = get_template(template_name)
  File "/usr/local/lib/python2.7/dist-packages/django/template/loader.py", line 138, in get_template
    template, origin = find_template(template_name)
  File "/usr/local/lib/python2.7/dist-packages/django/template/loader.py", line 127, in find_template
    source, display_name = loader(name, dirs)
  File "/usr/local/lib/python2.7/dist-packages/django/template/loader.py", line 43, in __call__
    return self.load_template(template_name, template_dirs)
  File "/usr/local/lib/python2.7/dist-packages/django/template/loader.py", line 49, in load_template
    template = get_template_from_string(source, origin, template_name)
  File "/usr/local/lib/python2.7/dist-packages/django/template/loader.py", line 149, in get_template_from_string
    return Template(source, origin, name)
  File "/usr/local/lib/python2.7/dist-packages/django/template/base.py", line 125, in __init__
    self.nodelist = compile_string(template_string, origin)
  File "/usr/local/lib/python2.7/dist-packages/django/template/base.py", line 153, in compile_string
    return parser.parse()
  File "/usr/local/lib/python2.7/dist-packages/django/template/base.py", line 278, in parse
    compiled_result = compile_func(self, token)
  File "/usr/local/lib/python2.7/dist-packages/django/template/loader_tags.py", line 215, in do_extends
    nodelist = parser.parse()
  File "/usr/local/lib/python2.7/dist-packages/django/template/base.py", line 278, in parse
    compiled_result = compile_func(self, token)
  File "/usr/local/lib/python2.7/dist-packages/django/template/loader_tags.py", line 190, in do_block
    nodelist = parser.parse(('endblock',))
  File "/usr/local/lib/python2.7/dist-packages/django/template/base.py", line 254, in parse
    filter_expression = self.compile_filter(token.contents)
  File "/usr/local/lib/python2.7/dist-packages/django/template/base.py", line 360, in compile_filter
    return FilterExpression(token, self)
  File "/usr/local/lib/python2.7/dist-packages/django/template/base.py", line 571, in __init__
    filter_func = parser.find_filter(filter_name)
  File "/usr/local/lib/python2.7/dist-packages/django/template/base.py", line 366, in find_filter
    raise TemplateSyntaxError("Invalid filter: '%s'" % filter_name)
TemplateSyntaxError: Invalid filter: 'as_bootstrap'
2014-08-08 15:37:21,325 [WARNING] django.request: Not Found: /accounts/login/signin.css
2014-08-08 15:37:22,966 [WARNING] django.request: Not Found: /accounts/login/signin.css
2014-08-08 15:38:49,558 [ERROR] django.request: Internal Server Error: /accounts/login/
Traceback (most recent call last):
  File "/usr/local/lib/python2.7/dist-packages/django/core/handlers/base.py", line 114, in get_response
    response = wrapped_callback(request, *callback_args, **callback_kwargs)
  File "/home/gk/django_test/django_test/views.py", line 22, in login
    return render_to_response('login.html', c, context_instance=RequestContext(request))
  File "/usr/local/lib/python2.7/dist-packages/django/shortcuts/__init__.py", line 29, in render_to_response
    return HttpResponse(loader.render_to_string(*args, **kwargs), **httpresponse_kwargs)
  File "/usr/local/lib/python2.7/dist-packages/django/template/loader.py", line 162, in render_to_string
    t = get_template(template_name)
  File "/usr/local/lib/python2.7/dist-packages/django/template/loader.py", line 138, in get_template
    template, origin = find_template(template_name)
  File "/usr/local/lib/python2.7/dist-packages/django/template/loader.py", line 127, in find_template
    source, display_name = loader(name, dirs)
  File "/usr/local/lib/python2.7/dist-packages/django/template/loader.py", line 43, in __call__
    return self.load_template(template_name, template_dirs)
  File "/usr/local/lib/python2.7/dist-packages/django/template/loader.py", line 49, in load_template
    template = get_template_from_string(source, origin, template_name)
  File "/usr/local/lib/python2.7/dist-packages/django/template/loader.py", line 149, in get_template_from_string
    return Template(source, origin, name)
  File "/usr/local/lib/python2.7/dist-packages/django/template/base.py", line 125, in __init__
    self.nodelist = compile_string(template_string, origin)
  File "/usr/local/lib/python2.7/dist-packages/django/template/base.py", line 153, in compile_string
    return parser.parse()
  File "/usr/local/lib/python2.7/dist-packages/django/template/base.py", line 278, in parse
    compiled_result = compile_func(self, token)
  File "/usr/local/lib/python2.7/dist-packages/django/template/loader_tags.py", line 215, in do_extends
    nodelist = parser.parse()
  File "/usr/local/lib/python2.7/dist-packages/django/template/base.py", line 278, in parse
    compiled_result = compile_func(self, token)
  File "/usr/local/lib/python2.7/dist-packages/django/template/loader_tags.py", line 190, in do_block
    nodelist = parser.parse(('endblock',))
  File "/usr/local/lib/python2.7/dist-packages/django/template/base.py", line 276, in parse
    self.invalid_block_tag(token, command, parse_until)
  File "/usr/local/lib/python2.7/dist-packages/django/template/base.py", line 331, in invalid_block_tag
    (command, get_text_list(["'%s'" % p for p in parse_until])))
TemplateSyntaxError: Invalid block tag: 'static', expected 'endblock'
2014-08-08 15:39:39,673 [ERROR] django.request: Internal Server Error: /accounts/login/
Traceback (most recent call last):
  File "/usr/local/lib/python2.7/dist-packages/django/core/handlers/base.py", line 114, in get_response
    response = wrapped_callback(request, *callback_args, **callback_kwargs)
  File "/home/gk/django_test/django_test/views.py", line 22, in login
    return render_to_response('login.html', c, context_instance=RequestContext(request))
  File "/usr/local/lib/python2.7/dist-packages/django/shortcuts/__init__.py", line 29, in render_to_response
    return HttpResponse(loader.render_to_string(*args, **kwargs), **httpresponse_kwargs)
  File "/usr/local/lib/python2.7/dist-packages/django/template/loader.py", line 162, in render_to_string
    t = get_template(template_name)
  File "/usr/local/lib/python2.7/dist-packages/django/template/loader.py", line 138, in get_template
    template, origin = find_template(template_name)
  File "/usr/local/lib/python2.7/dist-packages/django/template/loader.py", line 127, in find_template
    source, display_name = loader(name, dirs)
  File "/usr/local/lib/python2.7/dist-packages/django/template/loader.py", line 43, in __call__
    return self.load_template(template_name, template_dirs)
  File "/usr/local/lib/python2.7/dist-packages/django/template/loader.py", line 49, in load_template
    template = get_template_from_string(source, origin, template_name)
  File "/usr/local/lib/python2.7/dist-packages/django/template/loader.py", line 149, in get_template_from_string
    return Template(source, origin, name)
  File "/usr/local/lib/python2.7/dist-packages/django/template/base.py", line 125, in __init__
    self.nodelist = compile_string(template_string, origin)
  File "/usr/local/lib/python2.7/dist-packages/django/template/base.py", line 153, in compile_string
    return parser.parse()
  File "/usr/local/lib/python2.7/dist-packages/django/template/base.py", line 278, in parse
    compiled_result = compile_func(self, token)
  File "/usr/local/lib/python2.7/dist-packages/django/template/loader_tags.py", line 215, in do_extends
    nodelist = parser.parse()
  File "/usr/local/lib/python2.7/dist-packages/django/template/base.py", line 278, in parse
    compiled_result = compile_func(self, token)
  File "/usr/local/lib/python2.7/dist-packages/django/template/loader_tags.py", line 190, in do_block
    nodelist = parser.parse(('endblock',))
  File "/usr/local/lib/python2.7/dist-packages/django/template/base.py", line 276, in parse
    self.invalid_block_tag(token, command, parse_until)
  File "/usr/local/lib/python2.7/dist-packages/django/template/base.py", line 331, in invalid_block_tag
    (command, get_text_list(["'%s'" % p for p in parse_until])))
TemplateSyntaxError: Invalid block tag: 'static', expected 'endblock'
2014-08-08 15:41:02,847 [ERROR] django.request: Internal Server Error: /accounts/login/
Traceback (most recent call last):
  File "/usr/local/lib/python2.7/dist-packages/django/core/handlers/base.py", line 114, in get_response
    response = wrapped_callback(request, *callback_args, **callback_kwargs)
  File "/home/gk/django_test/django_test/views.py", line 22, in login
    return render_to_response('login.html', c, context_instance=RequestContext(request))
  File "/usr/local/lib/python2.7/dist-packages/django/shortcuts/__init__.py", line 29, in render_to_response
    return HttpResponse(loader.render_to_string(*args, **kwargs), **httpresponse_kwargs)
  File "/usr/local/lib/python2.7/dist-packages/django/template/loader.py", line 162, in render_to_string
    t = get_template(template_name)
  File "/usr/local/lib/python2.7/dist-packages/django/template/loader.py", line 138, in get_template
    template, origin = find_template(template_name)
  File "/usr/local/lib/python2.7/dist-packages/django/template/loader.py", line 127, in find_template
    source, display_name = loader(name, dirs)
  File "/usr/local/lib/python2.7/dist-packages/django/template/loader.py", line 43, in __call__
    return self.load_template(template_name, template_dirs)
  File "/usr/local/lib/python2.7/dist-packages/django/template/loader.py", line 49, in load_template
    template = get_template_from_string(source, origin, template_name)
  File "/usr/local/lib/python2.7/dist-packages/django/template/loader.py", line 149, in get_template_from_string
    return Template(source, origin, name)
  File "/usr/local/lib/python2.7/dist-packages/django/template/base.py", line 125, in __init__
    self.nodelist = compile_string(template_string, origin)
  File "/usr/local/lib/python2.7/dist-packages/django/template/base.py", line 153, in compile_string
    return parser.parse()
  File "/usr/local/lib/python2.7/dist-packages/django/template/base.py", line 278, in parse
    compiled_result = compile_func(self, token)
  File "/usr/local/lib/python2.7/dist-packages/django/template/loader_tags.py", line 215, in do_extends
    nodelist = parser.parse()
  File "/usr/local/lib/python2.7/dist-packages/django/template/base.py", line 278, in parse
    compiled_result = compile_func(self, token)
  File "/usr/local/lib/python2.7/dist-packages/django/template/loader_tags.py", line 190, in do_block
    nodelist = parser.parse(('endblock',))
  File "/usr/local/lib/python2.7/dist-packages/django/template/base.py", line 276, in parse
    self.invalid_block_tag(token, command, parse_until)
  File "/usr/local/lib/python2.7/dist-packages/django/template/base.py", line 331, in invalid_block_tag
    (command, get_text_list(["'%s'" % p for p in parse_until])))
TemplateSyntaxError: Invalid block tag: 'static', expected 'endblock'
2014-08-08 15:44:27,553 [ERROR] django.request: Internal Server Error: /accounts/login/
Traceback (most recent call last):
  File "/usr/local/lib/python2.7/dist-packages/django/core/handlers/base.py", line 114, in get_response
    response = wrapped_callback(request, *callback_args, **callback_kwargs)
  File "/home/gk/django_test/django_test/views.py", line 22, in login
    return render_to_response('login.html', c, context_instance=RequestContext(request))
  File "/usr/local/lib/python2.7/dist-packages/django/shortcuts/__init__.py", line 29, in render_to_response
    return HttpResponse(loader.render_to_string(*args, **kwargs), **httpresponse_kwargs)
  File "/usr/local/lib/python2.7/dist-packages/django/template/loader.py", line 162, in render_to_string
    t = get_template(template_name)
  File "/usr/local/lib/python2.7/dist-packages/django/template/loader.py", line 138, in get_template
    template, origin = find_template(template_name)
  File "/usr/local/lib/python2.7/dist-packages/django/template/loader.py", line 127, in find_template
    source, display_name = loader(name, dirs)
  File "/usr/local/lib/python2.7/dist-packages/django/template/loader.py", line 43, in __call__
    return self.load_template(template_name, template_dirs)
  File "/usr/local/lib/python2.7/dist-packages/django/template/loader.py", line 49, in load_template
    template = get_template_from_string(source, origin, template_name)
  File "/usr/local/lib/python2.7/dist-packages/django/template/loader.py", line 149, in get_template_from_string
    return Template(source, origin, name)
  File "/usr/local/lib/python2.7/dist-packages/django/template/base.py", line 125, in __init__
    self.nodelist = compile_string(template_string, origin)
  File "/usr/local/lib/python2.7/dist-packages/django/template/base.py", line 153, in compile_string
    return parser.parse()
  File "/usr/local/lib/python2.7/dist-packages/django/template/base.py", line 278, in parse
    compiled_result = compile_func(self, token)
  File "/usr/local/lib/python2.7/dist-packages/django/template/loader_tags.py", line 215, in do_extends
    nodelist = parser.parse()
  File "/usr/local/lib/python2.7/dist-packages/django/template/base.py", line 278, in parse
    compiled_result = compile_func(self, token)
  File "/usr/local/lib/python2.7/dist-packages/django/template/loader_tags.py", line 190, in do_block
    nodelist = parser.parse(('endblock',))
  File "/usr/local/lib/python2.7/dist-packages/django/template/base.py", line 276, in parse
    self.invalid_block_tag(token, command, parse_until)
  File "/usr/local/lib/python2.7/dist-packages/django/template/base.py", line 331, in invalid_block_tag
    (command, get_text_list(["'%s'" % p for p in parse_until])))
TemplateSyntaxError: Invalid block tag: 'static', expected 'endblock'
2014-08-08 16:44:19,338 [ERROR] django.request: Internal Server Error: /accounts/register/
Traceback (most recent call last):
  File "/usr/local/lib/python2.7/dist-packages/django/core/handlers/base.py", line 114, in get_response
    response = wrapped_callback(request, *callback_args, **callback_kwargs)
  File "/home/gk/django_test/django_test/views.py", line 56, in register_user
    return render_to_response('register.html', args)
  File "/usr/local/lib/python2.7/dist-packages/django/shortcuts/__init__.py", line 29, in render_to_response
    return HttpResponse(loader.render_to_string(*args, **kwargs), **httpresponse_kwargs)
  File "/usr/local/lib/python2.7/dist-packages/django/template/loader.py", line 162, in render_to_string
    t = get_template(template_name)
  File "/usr/local/lib/python2.7/dist-packages/django/template/loader.py", line 138, in get_template
    template, origin = find_template(template_name)
  File "/usr/local/lib/python2.7/dist-packages/django/template/loader.py", line 127, in find_template
    source, display_name = loader(name, dirs)
  File "/usr/local/lib/python2.7/dist-packages/django/template/loader.py", line 43, in __call__
    return self.load_template(template_name, template_dirs)
  File "/usr/local/lib/python2.7/dist-packages/django/template/loader.py", line 49, in load_template
    template = get_template_from_string(source, origin, template_name)
  File "/usr/local/lib/python2.7/dist-packages/django/template/loader.py", line 149, in get_template_from_string
    return Template(source, origin, name)
  File "/usr/local/lib/python2.7/dist-packages/django/template/base.py", line 125, in __init__
    self.nodelist = compile_string(template_string, origin)
  File "/usr/local/lib/python2.7/dist-packages/django/template/base.py", line 153, in compile_string
    return parser.parse()
  File "/usr/local/lib/python2.7/dist-packages/django/template/base.py", line 278, in parse
    compiled_result = compile_func(self, token)
  File "/usr/local/lib/python2.7/dist-packages/django/template/loader_tags.py", line 215, in do_extends
    nodelist = parser.parse()
  File "/usr/local/lib/python2.7/dist-packages/django/template/base.py", line 278, in parse
    compiled_result = compile_func(self, token)
  File "/usr/local/lib/python2.7/dist-packages/django/template/loader_tags.py", line 190, in do_block
    nodelist = parser.parse(('endblock',))
  File "/usr/local/lib/python2.7/dist-packages/django/template/base.py", line 276, in parse
    self.invalid_block_tag(token, command, parse_until)
  File "/usr/local/lib/python2.7/dist-packages/django/template/base.py", line 331, in invalid_block_tag
    (command, get_text_list(["'%s'" % p for p in parse_until])))
TemplateSyntaxError: Invalid block tag: 'bootstrap_form', expected 'endblock'
2014-08-08 16:57:14,753 [ERROR] django.request: Internal Server Error: /articles/create/
Traceback (most recent call last):
  File "/usr/local/lib/python2.7/dist-packages/django/core/handlers/base.py", line 132, in get_response
    raise ValueError("The view %s.%s didn't return an HttpResponse object." % (callback.__module__, view_name))
ValueError: The view article.views.create didn't return an HttpResponse object.
2014-08-08 16:58:03,624 [ERROR] django.request: Internal Server Error: /articles/create/
Traceback (most recent call last):
  File "/usr/local/lib/python2.7/dist-packages/django/core/handlers/base.py", line 132, in get_response
    raise ValueError("The view %s.%s didn't return an HttpResponse object." % (callback.__module__, view_name))
ValueError: The view article.views.create didn't return an HttpResponse object.
2014-08-08 16:59:40,673 [ERROR] django.request: Internal Server Error: /articles/create/
Traceback (most recent call last):
  File "/usr/local/lib/python2.7/dist-packages/django/core/handlers/base.py", line 132, in get_response
    raise ValueError("The view %s.%s didn't return an HttpResponse object." % (callback.__module__, view_name))
ValueError: The view article.views.create didn't return an HttpResponse object.
2014-08-08 17:01:58,021 [ERROR] django.request: Internal Server Error: /articles/create/
Traceback (most recent call last):
  File "/usr/local/lib/python2.7/dist-packages/django/core/handlers/base.py", line 114, in get_response
    response = wrapped_callback(request, *callback_args, **callback_kwargs)
  File "/home/gk/django_test/article/views.py", line 68, in create
    args['form'] = form
UnboundLocalError: local variable 'form' referenced before assignment
2014-08-08 17:02:43,433 [ERROR] django.request: Internal Server Error: /articles/create/
Traceback (most recent call last):
  File "/usr/local/lib/python2.7/dist-packages/django/core/handlers/base.py", line 114, in get_response
    response = wrapped_callback(request, *callback_args, **callback_kwargs)
  File "/home/gk/django_test/article/views.py", line 68, in create
    args['form'] = form
UnboundLocalError: local variable 'form' referenced before assignment
2014-08-08 17:02:50,233 [ERROR] django.request: Internal Server Error: /articles/create/
Traceback (most recent call last):
  File "/usr/local/lib/python2.7/dist-packages/django/core/handlers/base.py", line 101, in get_response
    resolver_match = resolver.resolve(request.path_info)
  File "/usr/local/lib/python2.7/dist-packages/django/core/urlresolvers.py", line 318, in resolve
    for pattern in self.url_patterns:
  File "/usr/local/lib/python2.7/dist-packages/django/core/urlresolvers.py", line 346, in url_patterns
    patterns = getattr(self.urlconf_module, "urlpatterns", self.urlconf_module)
  File "/usr/local/lib/python2.7/dist-packages/django/core/urlresolvers.py", line 341, in urlconf_module
    self._urlconf_module = import_module(self.urlconf_name)
  File "/usr/local/lib/python2.7/dist-packages/django/utils/importlib.py", line 40, in import_module
    __import__(name)
  File "/home/gk/django_test/django_test/urls.py", line 2, in <module>
    from article.views import HelloTemplate
  File "/home/gk/django_test/article/views.py", line 59
    if request.POST:
                   ^
IndentationError: unindent does not match any outer indentation level
2014-08-08 17:05:15,139 [WARNING] django.request: Not Found: /articles/favicon.ico
2014-08-08 17:42:37,169 [WARNING] django.request: Not Found: /HNAP1/
2014-08-08 17:42:37,179 [WARNING] django.request: Not Found: /JNAP/
2014-08-09 13:50:56,002 [WARNING] django.request: Not Found: /JNAP/
2014-08-09 13:50:58,633 [WARNING] django.request: Not Found: /HNAP1/
