2014-03-16 20:22:42,089 [ERROR] django.request: Internal Server Error: /articles/search/
Traceback (most recent call last):
  File "/usr/local/lib/python2.7/dist-packages/django/core/handlers/base.py", line 114, in get_response
    response = wrapped_callback(request, *callback_args, **callback_kwargs)
  File "/home/gk/django_test/article/views.py", line 109, in search_titles
    logr.debug(srch_text)
NameError: global name 'srch_text' is not defined
2014-03-16 20:22:42,089 [ERROR] django.request: Internal Server Error: /articles/search/
Traceback (most recent call last):
  File "/usr/local/lib/python2.7/dist-packages/django/core/handlers/base.py", line 114, in get_response
    response = wrapped_callback(request, *callback_args, **callback_kwargs)
  File "/home/gk/django_test/article/views.py", line 109, in search_titles
    logr.debug(srch_text)
NameError: global name 'srch_text' is not defined
2014-03-16 20:22:42,402 [ERROR] django.request: Internal Server Error: /articles/search/
Traceback (most recent call last):
  File "/usr/local/lib/python2.7/dist-packages/django/core/handlers/base.py", line 114, in get_response
    response = wrapped_callback(request, *callback_args, **callback_kwargs)
  File "/home/gk/django_test/article/views.py", line 109, in search_titles
    logr.debug(srch_text)
NameError: global name 'srch_text' is not defined
2014-03-16 20:22:42,403 [ERROR] django.request: Internal Server Error: /articles/search/
Traceback (most recent call last):
  File "/usr/local/lib/python2.7/dist-packages/django/core/handlers/base.py", line 114, in get_response
    response = wrapped_callback(request, *callback_args, **callback_kwargs)
  File "/home/gk/django_test/article/views.py", line 109, in search_titles
    logr.debug(srch_text)
NameError: global name 'srch_text' is not defined
2014-03-16 20:22:42,403 [ERROR] django.request: Internal Server Error: /articles/search/
Traceback (most recent call last):
  File "/usr/local/lib/python2.7/dist-packages/django/core/handlers/base.py", line 114, in get_response
    response = wrapped_callback(request, *callback_args, **callback_kwargs)
  File "/home/gk/django_test/article/views.py", line 109, in search_titles
    logr.debug(srch_text)
NameError: global name 'srch_text' is not defined
2014-03-16 20:22:42,474 [ERROR] django.request: Internal Server Error: /articles/search/
Traceback (most recent call last):
  File "/usr/local/lib/python2.7/dist-packages/django/core/handlers/base.py", line 114, in get_response
    response = wrapped_callback(request, *callback_args, **callback_kwargs)
  File "/home/gk/django_test/article/views.py", line 109, in search_titles
    logr.debug(srch_text)
NameError: global name 'srch_text' is not defined
2014-03-16 20:24:26,725 [ERROR] django.request: Internal Server Error: /articles/all
Traceback (most recent call last):
  File "/usr/local/lib/python2.7/dist-packages/django/core/handlers/base.py", line 90, in get_response
    response = middleware_method(request)
  File "/usr/local/lib/python2.7/dist-packages/django/middleware/common.py", line 71, in process_request
    if (not urlresolvers.is_valid_path(request.path_info, urlconf) and
  File "/usr/local/lib/python2.7/dist-packages/django/core/urlresolvers.py", line 573, in is_valid_path
    resolve(path, urlconf)
  File "/usr/local/lib/python2.7/dist-packages/django/core/urlresolvers.py", line 453, in resolve
    return get_resolver(urlconf).resolve(path)
  File "/usr/local/lib/python2.7/dist-packages/django/core/urlresolvers.py", line 318, in resolve
    for pattern in self.url_patterns:
  File "/usr/local/lib/python2.7/dist-packages/django/core/urlresolvers.py", line 346, in url_patterns
    patterns = getattr(self.urlconf_module, "urlpatterns", self.urlconf_module)
  File "/usr/local/lib/python2.7/dist-packages/django/core/urlresolvers.py", line 341, in urlconf_module
    self._urlconf_module = import_module(self.urlconf_name)
  File "/usr/local/lib/python2.7/dist-packages/django/utils/importlib.py", line 40, in import_module
    __import__(name)
  File "/home/gk/django_test/django_test/urls.py", line 2, in <module>
    from article.views import HelloTemplate
  File "/home/gk/django_test/article/views.py", line 110
    logr.debug(srch_text)
   ^
IndentationError: unexpected indent
2014-03-16 20:24:44,995 [ERROR] django.request: Internal Server Error: /articles/search/
Traceback (most recent call last):
  File "/usr/local/lib/python2.7/dist-packages/django/core/handlers/base.py", line 114, in get_response
    response = wrapped_callback(request, *callback_args, **callback_kwargs)
  File "/home/gk/django_test/article/views.py", line 109, in search_titles
    logr.debug(srch_text)
NameError: global name 'srch_text' is not defined
2014-03-16 20:24:45,087 [ERROR] django.request: Internal Server Error: /articles/search/
Traceback (most recent call last):
  File "/usr/local/lib/python2.7/dist-packages/django/core/handlers/base.py", line 114, in get_response
    response = wrapped_callback(request, *callback_args, **callback_kwargs)
  File "/home/gk/django_test/article/views.py", line 109, in search_titles
    logr.debug(srch_text)
NameError: global name 'srch_text' is not defined
2014-03-16 20:24:45,339 [ERROR] django.request: Internal Server Error: /articles/search/
Traceback (most recent call last):
  File "/usr/local/lib/python2.7/dist-packages/django/core/handlers/base.py", line 114, in get_response
    response = wrapped_callback(request, *callback_args, **callback_kwargs)
  File "/home/gk/django_test/article/views.py", line 109, in search_titles
    logr.debug(srch_text)
NameError: global name 'srch_text' is not defined
2014-03-16 20:25:08,478 [ERROR] django.request: Internal Server Error: /articles/search/
Traceback (most recent call last):
  File "/usr/local/lib/python2.7/dist-packages/django/core/handlers/base.py", line 114, in get_response
    response = wrapped_callback(request, *callback_args, **callback_kwargs)
  File "/home/gk/django_test/article/views.py", line 109, in search_titles
    logr.debug(srch_text)
NameError: global name 'srch_text' is not defined
2014-03-16 20:25:08,654 [ERROR] django.request: Internal Server Error: /articles/search/
Traceback (most recent call last):
  File "/usr/local/lib/python2.7/dist-packages/django/core/handlers/base.py", line 114, in get_response
    response = wrapped_callback(request, *callback_args, **callback_kwargs)
  File "/home/gk/django_test/article/views.py", line 109, in search_titles
    logr.debug(srch_text)
NameError: global name 'srch_text' is not defined
2014-03-16 20:25:08,842 [ERROR] django.request: Internal Server Error: /articles/search/
Traceback (most recent call last):
  File "/usr/local/lib/python2.7/dist-packages/django/core/handlers/base.py", line 114, in get_response
    response = wrapped_callback(request, *callback_args, **callback_kwargs)
  File "/home/gk/django_test/article/views.py", line 109, in search_titles
    logr.debug(srch_text)
NameError: global name 'srch_text' is not defined
2014-03-16 20:25:09,442 [ERROR] django.request: Internal Server Error: /articles/search/
Traceback (most recent call last):
  File "/usr/local/lib/python2.7/dist-packages/django/core/handlers/base.py", line 114, in get_response
    response = wrapped_callback(request, *callback_args, **callback_kwargs)
  File "/home/gk/django_test/article/views.py", line 109, in search_titles
    logr.debug(srch_text)
NameError: global name 'srch_text' is not defined
2014-03-16 20:25:09,478 [ERROR] django.request: Internal Server Error: /articles/search/
Traceback (most recent call last):
  File "/usr/local/lib/python2.7/dist-packages/django/core/handlers/base.py", line 114, in get_response
    response = wrapped_callback(request, *callback_args, **callback_kwargs)
  File "/home/gk/django_test/article/views.py", line 109, in search_titles
    logr.debug(srch_text)
NameError: global name 'srch_text' is not defined
2014-03-16 20:25:09,657 [ERROR] django.request: Internal Server Error: /articles/search/
Traceback (most recent call last):
  File "/usr/local/lib/python2.7/dist-packages/django/core/handlers/base.py", line 114, in get_response
    response = wrapped_callback(request, *callback_args, **callback_kwargs)
  File "/home/gk/django_test/article/views.py", line 109, in search_titles
    logr.debug(srch_text)
NameError: global name 'srch_text' is not defined
2014-03-16 20:25:09,924 [ERROR] django.request: Internal Server Error: /articles/search/
Traceback (most recent call last):
  File "/usr/local/lib/python2.7/dist-packages/django/core/handlers/base.py", line 114, in get_response
    response = wrapped_callback(request, *callback_args, **callback_kwargs)
  File "/home/gk/django_test/article/views.py", line 109, in search_titles
    logr.debug(srch_text)
NameError: global name 'srch_text' is not defined
2014-03-16 20:26:12,698 [ERROR] django.request: Internal Server Error: /articles/search/
Traceback (most recent call last):
  File "/usr/local/lib/python2.7/dist-packages/django/core/handlers/base.py", line 114, in get_response
    response = wrapped_callback(request, *callback_args, **callback_kwargs)
  File "/home/gk/django_test/article/views.py", line 110, in search_titles
    articles = Article.objects.filter(title__contains=srch_text)
NameError: global name 'srch_text' is not defined
2014-03-16 20:26:12,723 [ERROR] django.request: Internal Server Error: /articles/search/
Traceback (most recent call last):
  File "/usr/local/lib/python2.7/dist-packages/django/core/handlers/base.py", line 114, in get_response
    response = wrapped_callback(request, *callback_args, **callback_kwargs)
  File "/home/gk/django_test/article/views.py", line 110, in search_titles
    articles = Article.objects.filter(title__contains=srch_text)
NameError: global name 'srch_text' is not defined
2014-03-16 20:26:13,069 [ERROR] django.request: Internal Server Error: /articles/search/
Traceback (most recent call last):
  File "/usr/local/lib/python2.7/dist-packages/django/core/handlers/base.py", line 114, in get_response
    response = wrapped_callback(request, *callback_args, **callback_kwargs)
  File "/home/gk/django_test/article/views.py", line 110, in search_titles
    articles = Article.objects.filter(title__contains=srch_text)
NameError: global name 'srch_text' is not defined
2014-03-16 20:26:13,069 [ERROR] django.request: Internal Server Error: /articles/search/
Traceback (most recent call last):
  File "/usr/local/lib/python2.7/dist-packages/django/core/handlers/base.py", line 114, in get_response
    response = wrapped_callback(request, *callback_args, **callback_kwargs)
  File "/home/gk/django_test/article/views.py", line 110, in search_titles
    articles = Article.objects.filter(title__contains=srch_text)
NameError: global name 'srch_text' is not defined
2014-03-16 20:26:37,688 [ERROR] django.request: Internal Server Error: /articles/search/
Traceback (most recent call last):
  File "/usr/local/lib/python2.7/dist-packages/django/core/handlers/base.py", line 114, in get_response
    response = wrapped_callback(request, *callback_args, **callback_kwargs)
  File "/home/gk/django_test/article/views.py", line 110, in search_titles
    articles = Article.objects.filter(title__contains=srch_text)
NameError: global name 'srch_text' is not defined
2014-03-16 20:26:37,845 [ERROR] django.request: Internal Server Error: /articles/search/
Traceback (most recent call last):
  File "/usr/local/lib/python2.7/dist-packages/django/core/handlers/base.py", line 114, in get_response
    response = wrapped_callback(request, *callback_args, **callback_kwargs)
  File "/home/gk/django_test/article/views.py", line 110, in search_titles
    articles = Article.objects.filter(title__contains=srch_text)
NameError: global name 'srch_text' is not defined
2014-03-16 20:26:38,005 [ERROR] django.request: Internal Server Error: /articles/search/
Traceback (most recent call last):
  File "/usr/local/lib/python2.7/dist-packages/django/core/handlers/base.py", line 114, in get_response
    response = wrapped_callback(request, *callback_args, **callback_kwargs)
  File "/home/gk/django_test/article/views.py", line 110, in search_titles
    articles = Article.objects.filter(title__contains=srch_text)
NameError: global name 'srch_text' is not defined
2014-03-16 20:26:38,362 [ERROR] django.request: Internal Server Error: /articles/search/
Traceback (most recent call last):
  File "/usr/local/lib/python2.7/dist-packages/django/core/handlers/base.py", line 114, in get_response
    response = wrapped_callback(request, *callback_args, **callback_kwargs)
  File "/home/gk/django_test/article/views.py", line 110, in search_titles
    articles = Article.objects.filter(title__contains=srch_text)
NameError: global name 'srch_text' is not defined
2014-03-16 20:26:38,459 [ERROR] django.request: Internal Server Error: /articles/search/
Traceback (most recent call last):
  File "/usr/local/lib/python2.7/dist-packages/django/core/handlers/base.py", line 114, in get_response
    response = wrapped_callback(request, *callback_args, **callback_kwargs)
  File "/home/gk/django_test/article/views.py", line 110, in search_titles
    articles = Article.objects.filter(title__contains=srch_text)
NameError: global name 'srch_text' is not defined
2014-03-16 20:26:38,532 [ERROR] django.request: Internal Server Error: /articles/search/
Traceback (most recent call last):
  File "/usr/local/lib/python2.7/dist-packages/django/core/handlers/base.py", line 114, in get_response
    response = wrapped_callback(request, *callback_args, **callback_kwargs)
  File "/home/gk/django_test/article/views.py", line 110, in search_titles
    articles = Article.objects.filter(title__contains=srch_text)
NameError: global name 'srch_text' is not defined
2014-03-16 20:26:38,790 [ERROR] django.request: Internal Server Error: /articles/search/
Traceback (most recent call last):
  File "/usr/local/lib/python2.7/dist-packages/django/core/handlers/base.py", line 114, in get_response
    response = wrapped_callback(request, *callback_args, **callback_kwargs)
  File "/home/gk/django_test/article/views.py", line 110, in search_titles
    articles = Article.objects.filter(title__contains=srch_text)
NameError: global name 'srch_text' is not defined
2014-03-16 20:26:38,843 [ERROR] django.request: Internal Server Error: /articles/search/
Traceback (most recent call last):
  File "/usr/local/lib/python2.7/dist-packages/django/core/handlers/base.py", line 114, in get_response
    response = wrapped_callback(request, *callback_args, **callback_kwargs)
  File "/home/gk/django_test/article/views.py", line 110, in search_titles
    articles = Article.objects.filter(title__contains=srch_text)
NameError: global name 'srch_text' is not defined
2014-03-17 15:13:51,963 [ERROR] django.request: Internal Server Error: /contact
Traceback (most recent call last):
  File "/usr/local/lib/python2.7/dist-packages/django/core/handlers/base.py", line 90, in get_response
    response = middleware_method(request)
  File "/usr/local/lib/python2.7/dist-packages/django/middleware/common.py", line 71, in process_request
    if (not urlresolvers.is_valid_path(request.path_info, urlconf) and
  File "/usr/local/lib/python2.7/dist-packages/django/core/urlresolvers.py", line 573, in is_valid_path
    resolve(path, urlconf)
  File "/usr/local/lib/python2.7/dist-packages/django/core/urlresolvers.py", line 453, in resolve
    return get_resolver(urlconf).resolve(path)
  File "/usr/local/lib/python2.7/dist-packages/django/core/urlresolvers.py", line 318, in resolve
    for pattern in self.url_patterns:
  File "/usr/local/lib/python2.7/dist-packages/django/core/urlresolvers.py", line 346, in url_patterns
    patterns = getattr(self.urlconf_module, "urlpatterns", self.urlconf_module)
  File "/usr/local/lib/python2.7/dist-packages/django/core/urlresolvers.py", line 341, in urlconf_module
    self._urlconf_module = import_module(self.urlconf_name)
  File "/usr/local/lib/python2.7/dist-packages/django/utils/importlib.py", line 40, in import_module
    __import__(name)
  File "/home/gk/django_test/django_test/urls.py", line 6, in <module>
    from django_test.forms import ContactForm1, ContactForm2, ContactForm3
ImportError: cannot import name ContactForm3
2014-03-17 15:18:34,572 [ERROR] django.request: Internal Server Error: /contact
Traceback (most recent call last):
  File "/usr/local/lib/python2.7/dist-packages/django/core/handlers/base.py", line 90, in get_response
    response = middleware_method(request)
  File "/usr/local/lib/python2.7/dist-packages/django/middleware/common.py", line 71, in process_request
    if (not urlresolvers.is_valid_path(request.path_info, urlconf) and
  File "/usr/local/lib/python2.7/dist-packages/django/core/urlresolvers.py", line 573, in is_valid_path
    resolve(path, urlconf)
  File "/usr/local/lib/python2.7/dist-packages/django/core/urlresolvers.py", line 453, in resolve
    return get_resolver(urlconf).resolve(path)
  File "/usr/local/lib/python2.7/dist-packages/django/core/urlresolvers.py", line 318, in resolve
    for pattern in self.url_patterns:
  File "/usr/local/lib/python2.7/dist-packages/django/core/urlresolvers.py", line 346, in url_patterns
    patterns = getattr(self.urlconf_module, "urlpatterns", self.urlconf_module)
  File "/usr/local/lib/python2.7/dist-packages/django/core/urlresolvers.py", line 341, in urlconf_module
    self._urlconf_module = import_module(self.urlconf_name)
  File "/usr/local/lib/python2.7/dist-packages/django/utils/importlib.py", line 40, in import_module
    __import__(name)
  File "/home/gk/django_test/django_test/urls.py", line 6, in <module>
    from django_test.forms import ContactForm3, ContactForm2, ContactForm1
ImportError: cannot import name ContactForm3
2014-03-17 15:19:33,286 [ERROR] django.request: Internal Server Error: /contact
Traceback (most recent call last):
  File "/usr/local/lib/python2.7/dist-packages/django/core/handlers/base.py", line 90, in get_response
    response = middleware_method(request)
  File "/usr/local/lib/python2.7/dist-packages/django/middleware/common.py", line 71, in process_request
    if (not urlresolvers.is_valid_path(request.path_info, urlconf) and
  File "/usr/local/lib/python2.7/dist-packages/django/core/urlresolvers.py", line 573, in is_valid_path
    resolve(path, urlconf)
  File "/usr/local/lib/python2.7/dist-packages/django/core/urlresolvers.py", line 453, in resolve
    return get_resolver(urlconf).resolve(path)
  File "/usr/local/lib/python2.7/dist-packages/django/core/urlresolvers.py", line 318, in resolve
    for pattern in self.url_patterns:
  File "/usr/local/lib/python2.7/dist-packages/django/core/urlresolvers.py", line 346, in url_patterns
    patterns = getattr(self.urlconf_module, "urlpatterns", self.urlconf_module)
  File "/usr/local/lib/python2.7/dist-packages/django/core/urlresolvers.py", line 341, in urlconf_module
    self._urlconf_module = import_module(self.urlconf_name)
  File "/usr/local/lib/python2.7/dist-packages/django/utils/importlib.py", line 40, in import_module
    __import__(name)
  File "/home/gk/django_test/django_test/urls.py", line 6, in <module>
    from django_test.forms import ContactForm3, ContactForm2, ContactForm1
ImportError: cannot import name ContactForm3
2014-03-17 15:20:21,853 [ERROR] django.request: Internal Server Error: /contact
Traceback (most recent call last):
  File "/usr/local/lib/python2.7/dist-packages/django/core/handlers/base.py", line 90, in get_response
    response = middleware_method(request)
  File "/usr/local/lib/python2.7/dist-packages/django/middleware/common.py", line 71, in process_request
    if (not urlresolvers.is_valid_path(request.path_info, urlconf) and
  File "/usr/local/lib/python2.7/dist-packages/django/core/urlresolvers.py", line 573, in is_valid_path
    resolve(path, urlconf)
  File "/usr/local/lib/python2.7/dist-packages/django/core/urlresolvers.py", line 453, in resolve
    return get_resolver(urlconf).resolve(path)
  File "/usr/local/lib/python2.7/dist-packages/django/core/urlresolvers.py", line 318, in resolve
    for pattern in self.url_patterns:
  File "/usr/local/lib/python2.7/dist-packages/django/core/urlresolvers.py", line 346, in url_patterns
    patterns = getattr(self.urlconf_module, "urlpatterns", self.urlconf_module)
  File "/usr/local/lib/python2.7/dist-packages/django/core/urlresolvers.py", line 341, in urlconf_module
    self._urlconf_module = import_module(self.urlconf_name)
  File "/usr/local/lib/python2.7/dist-packages/django/utils/importlib.py", line 40, in import_module
    __import__(name)
  File "/home/gk/django_test/django_test/urls.py", line 27, in <module>
    url(r'^contact/$', ContactWizard.as_view([ContactForm1, ContactForm2, ContactForm3])),
AttributeError: 'function' object has no attribute 'as_view'
2014-03-17 15:23:55,602 [ERROR] django.request: Internal Server Error: /contact
Traceback (most recent call last):
  File "/usr/local/lib/python2.7/dist-packages/django/core/handlers/base.py", line 90, in get_response
    response = middleware_method(request)
  File "/usr/local/lib/python2.7/dist-packages/django/middleware/common.py", line 71, in process_request
    if (not urlresolvers.is_valid_path(request.path_info, urlconf) and
  File "/usr/local/lib/python2.7/dist-packages/django/core/urlresolvers.py", line 573, in is_valid_path
    resolve(path, urlconf)
  File "/usr/local/lib/python2.7/dist-packages/django/core/urlresolvers.py", line 453, in resolve
    return get_resolver(urlconf).resolve(path)
  File "/usr/local/lib/python2.7/dist-packages/django/core/urlresolvers.py", line 318, in resolve
    for pattern in self.url_patterns:
  File "/usr/local/lib/python2.7/dist-packages/django/core/urlresolvers.py", line 346, in url_patterns
    patterns = getattr(self.urlconf_module, "urlpatterns", self.urlconf_module)
  File "/usr/local/lib/python2.7/dist-packages/django/core/urlresolvers.py", line 341, in urlconf_module
    self._urlconf_module = import_module(self.urlconf_name)
  File "/usr/local/lib/python2.7/dist-packages/django/utils/importlib.py", line 40, in import_module
    __import__(name)
  File "/home/gk/django_test/django_test/urls.py", line 27, in <module>
    url(r'^contact/$', ContactWizard.as_view([ContactForm1, ContactForm2, ContactForm3])),
AttributeError: 'function' object has no attribute 'as_view'
2014-03-17 15:31:52,865 [ERROR] django.request: Internal Server Error: /contact
Traceback (most recent call last):
  File "/usr/local/lib/python2.7/dist-packages/django/core/handlers/base.py", line 90, in get_response
    response = middleware_method(request)
  File "/usr/local/lib/python2.7/dist-packages/django/middleware/common.py", line 71, in process_request
    if (not urlresolvers.is_valid_path(request.path_info, urlconf) and
  File "/usr/local/lib/python2.7/dist-packages/django/core/urlresolvers.py", line 573, in is_valid_path
    resolve(path, urlconf)
  File "/usr/local/lib/python2.7/dist-packages/django/core/urlresolvers.py", line 453, in resolve
    return get_resolver(urlconf).resolve(path)
  File "/usr/local/lib/python2.7/dist-packages/django/core/urlresolvers.py", line 318, in resolve
    for pattern in self.url_patterns:
  File "/usr/local/lib/python2.7/dist-packages/django/core/urlresolvers.py", line 346, in url_patterns
    patterns = getattr(self.urlconf_module, "urlpatterns", self.urlconf_module)
  File "/usr/local/lib/python2.7/dist-packages/django/core/urlresolvers.py", line 341, in urlconf_module
    self._urlconf_module = import_module(self.urlconf_name)
  File "/usr/local/lib/python2.7/dist-packages/django/utils/importlib.py", line 40, in import_module
    __import__(name)
  File "/home/gk/django_test/django_test/urls.py", line 9, in <module>
    class ContactWizard(WizardView):
NameError: name 'WizardView' is not defined
2014-03-17 15:33:00,909 [ERROR] django.request: Internal Server Error: /contact
Traceback (most recent call last):
  File "/usr/local/lib/python2.7/dist-packages/django/core/handlers/base.py", line 90, in get_response
    response = middleware_method(request)
  File "/usr/local/lib/python2.7/dist-packages/django/middleware/common.py", line 71, in process_request
    if (not urlresolvers.is_valid_path(request.path_info, urlconf) and
  File "/usr/local/lib/python2.7/dist-packages/django/core/urlresolvers.py", line 573, in is_valid_path
    resolve(path, urlconf)
  File "/usr/local/lib/python2.7/dist-packages/django/core/urlresolvers.py", line 453, in resolve
    return get_resolver(urlconf).resolve(path)
  File "/usr/local/lib/python2.7/dist-packages/django/core/urlresolvers.py", line 318, in resolve
    for pattern in self.url_patterns:
  File "/usr/local/lib/python2.7/dist-packages/django/core/urlresolvers.py", line 346, in url_patterns
    patterns = getattr(self.urlconf_module, "urlpatterns", self.urlconf_module)
  File "/usr/local/lib/python2.7/dist-packages/django/core/urlresolvers.py", line 341, in urlconf_module
    self._urlconf_module = import_module(self.urlconf_name)
  File "/usr/local/lib/python2.7/dist-packages/django/utils/importlib.py", line 40, in import_module
    __import__(name)
  File "/home/gk/django_test/django_test/urls.py", line 27, in <module>
    url(r'^contact/$', ContactWizard.as_view()),
AttributeError: 'function' object has no attribute 'as_view'
2014-03-17 15:40:34,016 [ERROR] django.request: Internal Server Error: /contact
Traceback (most recent call last):
  File "/usr/local/lib/python2.7/dist-packages/django/core/handlers/base.py", line 90, in get_response
    response = middleware_method(request)
  File "/usr/local/lib/python2.7/dist-packages/django/middleware/common.py", line 71, in process_request
    if (not urlresolvers.is_valid_path(request.path_info, urlconf) and
  File "/usr/local/lib/python2.7/dist-packages/django/core/urlresolvers.py", line 573, in is_valid_path
    resolve(path, urlconf)
  File "/usr/local/lib/python2.7/dist-packages/django/core/urlresolvers.py", line 453, in resolve
    return get_resolver(urlconf).resolve(path)
  File "/usr/local/lib/python2.7/dist-packages/django/core/urlresolvers.py", line 318, in resolve
    for pattern in self.url_patterns:
  File "/usr/local/lib/python2.7/dist-packages/django/core/urlresolvers.py", line 346, in url_patterns
    patterns = getattr(self.urlconf_module, "urlpatterns", self.urlconf_module)
  File "/usr/local/lib/python2.7/dist-packages/django/core/urlresolvers.py", line 341, in urlconf_module
    self._urlconf_module = import_module(self.urlconf_name)
  File "/usr/local/lib/python2.7/dist-packages/django/utils/importlib.py", line 40, in import_module
    __import__(name)
  File "/home/gk/django_test/django_test/urls.py", line 14
    wiz = ContactWizard.as_view([ContactForm1, ContactForm2], initial_dict=initial)
      ^
SyntaxError: invalid syntax
2014-03-17 15:41:37,496 [ERROR] django.request: Internal Server Error: /contact
Traceback (most recent call last):
  File "/usr/local/lib/python2.7/dist-packages/django/core/handlers/base.py", line 90, in get_response
    response = middleware_method(request)
  File "/usr/local/lib/python2.7/dist-packages/django/middleware/common.py", line 71, in process_request
    if (not urlresolvers.is_valid_path(request.path_info, urlconf) and
  File "/usr/local/lib/python2.7/dist-packages/django/core/urlresolvers.py", line 573, in is_valid_path
    resolve(path, urlconf)
  File "/usr/local/lib/python2.7/dist-packages/django/core/urlresolvers.py", line 453, in resolve
    return get_resolver(urlconf).resolve(path)
  File "/usr/local/lib/python2.7/dist-packages/django/core/urlresolvers.py", line 318, in resolve
    for pattern in self.url_patterns:
  File "/usr/local/lib/python2.7/dist-packages/django/core/urlresolvers.py", line 346, in url_patterns
    patterns = getattr(self.urlconf_module, "urlpatterns", self.urlconf_module)
  File "/usr/local/lib/python2.7/dist-packages/django/core/urlresolvers.py", line 341, in urlconf_module
    self._urlconf_module = import_module(self.urlconf_name)
  File "/usr/local/lib/python2.7/dist-packages/django/utils/importlib.py", line 40, in import_module
    __import__(name)
  File "/home/gk/django_test/django_test/urls.py", line 14
    wiz = ContactWizard.as_view([ContactForm1, ContactForm2], initial_dict=initial)(request)
      ^
SyntaxError: invalid syntax
2014-03-17 15:41:55,463 [ERROR] django.request: Internal Server Error: /contact
Traceback (most recent call last):
  File "/usr/local/lib/python2.7/dist-packages/django/core/handlers/base.py", line 90, in get_response
    response = middleware_method(request)
  File "/usr/local/lib/python2.7/dist-packages/django/middleware/common.py", line 71, in process_request
    if (not urlresolvers.is_valid_path(request.path_info, urlconf) and
  File "/usr/local/lib/python2.7/dist-packages/django/core/urlresolvers.py", line 573, in is_valid_path
    resolve(path, urlconf)
  File "/usr/local/lib/python2.7/dist-packages/django/core/urlresolvers.py", line 453, in resolve
    return get_resolver(urlconf).resolve(path)
  File "/usr/local/lib/python2.7/dist-packages/django/core/urlresolvers.py", line 318, in resolve
    for pattern in self.url_patterns:
  File "/usr/local/lib/python2.7/dist-packages/django/core/urlresolvers.py", line 346, in url_patterns
    patterns = getattr(self.urlconf_module, "urlpatterns", self.urlconf_module)
  File "/usr/local/lib/python2.7/dist-packages/django/core/urlresolvers.py", line 341, in urlconf_module
    self._urlconf_module = import_module(self.urlconf_name)
  File "/usr/local/lib/python2.7/dist-packages/django/utils/importlib.py", line 40, in import_module
    __import__(name)
  File "/home/gk/django_test/django_test/urls.py", line 44
    
   ^
SyntaxError: invalid syntax
2014-03-17 15:43:18,038 [ERROR] django.request: Internal Server Error: /contact
Traceback (most recent call last):
  File "/usr/local/lib/python2.7/dist-packages/django/core/handlers/base.py", line 90, in get_response
    response = middleware_method(request)
  File "/usr/local/lib/python2.7/dist-packages/django/middleware/common.py", line 71, in process_request
    if (not urlresolvers.is_valid_path(request.path_info, urlconf) and
  File "/usr/local/lib/python2.7/dist-packages/django/core/urlresolvers.py", line 573, in is_valid_path
    resolve(path, urlconf)
  File "/usr/local/lib/python2.7/dist-packages/django/core/urlresolvers.py", line 453, in resolve
    return get_resolver(urlconf).resolve(path)
  File "/usr/local/lib/python2.7/dist-packages/django/core/urlresolvers.py", line 318, in resolve
    for pattern in self.url_patterns:
  File "/usr/local/lib/python2.7/dist-packages/django/core/urlresolvers.py", line 346, in url_patterns
    patterns = getattr(self.urlconf_module, "urlpatterns", self.urlconf_module)
  File "/usr/local/lib/python2.7/dist-packages/django/core/urlresolvers.py", line 341, in urlconf_module
    self._urlconf_module = import_module(self.urlconf_name)
  File "/usr/local/lib/python2.7/dist-packages/django/utils/importlib.py", line 40, in import_module
    __import__(name)
  File "/home/gk/django_test/django_test/urls.py", line 16, in <module>
    wiz = ContactWizard.as_view([ContactForm1, ContactForm2], initial_dict=initial)
AttributeError: 'function' object has no attribute 'as_view'
2014-03-17 15:50:29,466 [ERROR] django.request: Internal Server Error: /contact
Traceback (most recent call last):
  File "/usr/local/lib/python2.7/dist-packages/django/core/handlers/base.py", line 90, in get_response
    response = middleware_method(request)
  File "/usr/local/lib/python2.7/dist-packages/django/middleware/common.py", line 71, in process_request
    if (not urlresolvers.is_valid_path(request.path_info, urlconf) and
  File "/usr/local/lib/python2.7/dist-packages/django/core/urlresolvers.py", line 573, in is_valid_path
    resolve(path, urlconf)
  File "/usr/local/lib/python2.7/dist-packages/django/core/urlresolvers.py", line 453, in resolve
    return get_resolver(urlconf).resolve(path)
  File "/usr/local/lib/python2.7/dist-packages/django/core/urlresolvers.py", line 318, in resolve
    for pattern in self.url_patterns:
  File "/usr/local/lib/python2.7/dist-packages/django/core/urlresolvers.py", line 346, in url_patterns
    patterns = getattr(self.urlconf_module, "urlpatterns", self.urlconf_module)
  File "/usr/local/lib/python2.7/dist-packages/django/core/urlresolvers.py", line 341, in urlconf_module
    self._urlconf_module = import_module(self.urlconf_name)
  File "/usr/local/lib/python2.7/dist-packages/django/utils/importlib.py", line 40, in import_module
    __import__(name)
  File "/home/gk/django_test/django_test/urls.py", line 27, in <module>
    (r'^contact/$', ContactWizard.as_view([ContactForm1, ContactForm2])),
AttributeError: 'function' object has no attribute 'as_view'
2014-03-17 15:52:46,295 [ERROR] django.request: Internal Server Error: /contact
Traceback (most recent call last):
  File "/usr/local/lib/python2.7/dist-packages/django/core/handlers/base.py", line 90, in get_response
    response = middleware_method(request)
  File "/usr/local/lib/python2.7/dist-packages/django/middleware/common.py", line 71, in process_request
    if (not urlresolvers.is_valid_path(request.path_info, urlconf) and
  File "/usr/local/lib/python2.7/dist-packages/django/core/urlresolvers.py", line 573, in is_valid_path
    resolve(path, urlconf)
  File "/usr/local/lib/python2.7/dist-packages/django/core/urlresolvers.py", line 453, in resolve
    return get_resolver(urlconf).resolve(path)
  File "/usr/local/lib/python2.7/dist-packages/django/core/urlresolvers.py", line 318, in resolve
    for pattern in self.url_patterns:
  File "/usr/local/lib/python2.7/dist-packages/django/core/urlresolvers.py", line 346, in url_patterns
    patterns = getattr(self.urlconf_module, "urlpatterns", self.urlconf_module)
  File "/usr/local/lib/python2.7/dist-packages/django/core/urlresolvers.py", line 341, in urlconf_module
    self._urlconf_module = import_module(self.urlconf_name)
  File "/usr/local/lib/python2.7/dist-packages/django/utils/importlib.py", line 40, in import_module
    __import__(name)
  File "/home/gk/django_test/django_test/urls.py", line 27, in <module>
    url(r'^contact/$', ContactWizard.as_view([ContactForm1, ContactForm2])),
AttributeError: 'function' object has no attribute 'as_view'
2014-03-17 16:26:05,549 [ERROR] django.request: Internal Server Error: /contact
Traceback (most recent call last):
  File "/usr/local/lib/python2.7/dist-packages/django/core/handlers/base.py", line 90, in get_response
    response = middleware_method(request)
  File "/usr/local/lib/python2.7/dist-packages/django/middleware/common.py", line 71, in process_request
    if (not urlresolvers.is_valid_path(request.path_info, urlconf) and
  File "/usr/local/lib/python2.7/dist-packages/django/core/urlresolvers.py", line 573, in is_valid_path
    resolve(path, urlconf)
  File "/usr/local/lib/python2.7/dist-packages/django/core/urlresolvers.py", line 453, in resolve
    return get_resolver(urlconf).resolve(path)
  File "/usr/local/lib/python2.7/dist-packages/django/core/urlresolvers.py", line 318, in resolve
    for pattern in self.url_patterns:
  File "/usr/local/lib/python2.7/dist-packages/django/core/urlresolvers.py", line 346, in url_patterns
    patterns = getattr(self.urlconf_module, "urlpatterns", self.urlconf_module)
  File "/usr/local/lib/python2.7/dist-packages/django/core/urlresolvers.py", line 341, in urlconf_module
    self._urlconf_module = import_module(self.urlconf_name)
  File "/usr/local/lib/python2.7/dist-packages/django/utils/importlib.py", line 40, in import_module
    __import__(name)
  File "/home/gk/django_test/django_test/urls.py", line 27, in <module>
    url(r'^contact/$', ContactWizard.as_view([ContactForm1, ContactForm2])),
AttributeError: 'function' object has no attribute 'as_view'
2014-03-17 17:11:43,994 [ERROR] django.request: Internal Server Error: /contact/
Traceback (most recent call last):
  File "/usr/local/lib/python2.7/dist-packages/django/core/handlers/base.py", line 114, in get_response
    response = wrapped_callback(request, *callback_args, **callback_kwargs)
  File "/usr/local/lib/python2.7/dist-packages/django/views/generic/base.py", line 69, in view
    return self.dispatch(request, *args, **kwargs)
  File "/usr/local/lib/python2.7/dist-packages/django/contrib/formtools/wizard/views.py", line 236, in dispatch
    response = super(WizardView, self).dispatch(request, *args, **kwargs)
  File "/usr/local/lib/python2.7/dist-packages/django/views/generic/base.py", line 87, in dispatch
    return handler(request, *args, **kwargs)
  File "/usr/local/lib/python2.7/dist-packages/django/contrib/formtools/wizard/views.py", line 297, in post
    return self.render_done(form, **kwargs)
  File "/usr/local/lib/python2.7/dist-packages/django/contrib/formtools/wizard/views.py", line 350, in render_done
    done_response = self.done(final_form_list, **kwargs)
  File "/home/gk/django_test/django_test/views.py", line 67, in done
    logr.debug(form_data[1]['sender'])
  File "/home/gk/django_test/django_test/views.py", line 76, in process_form_data
    
IndexError: list index out of range
2014-03-17 17:12:46,548 [ERROR] django.request: Internal Server Error: /contact/
Traceback (most recent call last):
  File "/usr/local/lib/python2.7/dist-packages/django/core/handlers/base.py", line 114, in get_response
    response = wrapped_callback(request, *callback_args, **callback_kwargs)
  File "/usr/local/lib/python2.7/dist-packages/django/views/generic/base.py", line 69, in view
    return self.dispatch(request, *args, **kwargs)
  File "/usr/local/lib/python2.7/dist-packages/django/contrib/formtools/wizard/views.py", line 236, in dispatch
    response = super(WizardView, self).dispatch(request, *args, **kwargs)
  File "/usr/local/lib/python2.7/dist-packages/django/views/generic/base.py", line 87, in dispatch
    return handler(request, *args, **kwargs)
  File "/usr/local/lib/python2.7/dist-packages/django/contrib/formtools/wizard/views.py", line 297, in post
    return self.render_done(form, **kwargs)
  File "/usr/local/lib/python2.7/dist-packages/django/contrib/formtools/wizard/views.py", line 350, in render_done
    done_response = self.done(final_form_list, **kwargs)
  File "/home/gk/django_test/django_test/views.py", line 67, in done
    logr.debug(form_data[1]['sender'])
  File "/home/gk/django_test/django_test/views.py", line 76, in process_form_data
    class ContactWizard(SessionWizardView):
IndexError: list index out of range
2014-03-17 17:15:50,305 [ERROR] django.request: Internal Server Error: /contact/
Traceback (most recent call last):
  File "/usr/local/lib/python2.7/dist-packages/django/core/handlers/base.py", line 114, in get_response
    response = wrapped_callback(request, *callback_args, **callback_kwargs)
  File "/usr/local/lib/python2.7/dist-packages/django/views/generic/base.py", line 69, in view
    return self.dispatch(request, *args, **kwargs)
  File "/usr/local/lib/python2.7/dist-packages/django/contrib/formtools/wizard/views.py", line 236, in dispatch
    response = super(WizardView, self).dispatch(request, *args, **kwargs)
  File "/usr/local/lib/python2.7/dist-packages/django/views/generic/base.py", line 87, in dispatch
    return handler(request, *args, **kwargs)
  File "/usr/local/lib/python2.7/dist-packages/django/contrib/formtools/wizard/views.py", line 297, in post
    return self.render_done(form, **kwargs)
  File "/usr/local/lib/python2.7/dist-packages/django/contrib/formtools/wizard/views.py", line 350, in render_done
    done_response = self.done(final_form_list, **kwargs)
  File "/home/gk/django_test/django_test/views.py", line 80, in done
    form_data = process_form_data(form_list)
  File "/home/gk/django_test/django_test/views.py", line 72, in process_form_data
    ['gk@luminoso.com'], fail_silently=False)
  File "/usr/local/lib/python2.7/dist-packages/django/core/mail/__init__.py", line 50, in send_mail
    connection=connection).send()
  File "/usr/local/lib/python2.7/dist-packages/django/core/mail/message.py", line 274, in send
    return self.get_connection(fail_silently).send_messages([self])
  File "/usr/local/lib/python2.7/dist-packages/django/core/mail/backends/smtp.py", line 87, in send_messages
    new_conn_created = self.open()
  File "/usr/local/lib/python2.7/dist-packages/django/core/mail/backends/smtp.py", line 48, in open
    local_hostname=DNS_NAME.get_fqdn())
  File "/usr/lib/python2.7/smtplib.py", line 251, in __init__
    (code, msg) = self.connect(host, port)
  File "/usr/lib/python2.7/smtplib.py", line 311, in connect
    self.sock = self._get_socket(host, port, self.timeout)
  File "/usr/lib/python2.7/smtplib.py", line 286, in _get_socket
    return socket.create_connection((host, port), timeout)
  File "/usr/lib/python2.7/socket.py", line 571, in create_connection
    raise err
error: [Errno 111] Connection refused
2014-03-17 17:36:20,170 [ERROR] django.request: Internal Server Error: /
Traceback (most recent call last):
  File "/usr/local/lib/python2.7/dist-packages/django/core/handlers/base.py", line 114, in get_response
    response = wrapped_callback(request, *callback_args, **callback_kwargs)
  File "/home/gk/django_test/django_test/views.py", line 15, in index
    PARENT_DIR = os.path.abspath(os.path.dirname(__file__) + "/../")
NameError: global name 'os' is not defined
2014-03-17 17:41:44,132 [ERROR] django.request: Internal Server Error: /
Traceback (most recent call last):
  File "/usr/local/lib/python2.7/dist-packages/django/core/handlers/base.py", line 114, in get_response
    response = wrapped_callback(request, *callback_args, **callback_kwargs)
  File "/home/gk/django_test/django_test/views.py", line 17, in index
    logr.debug(EMAIL_PW)
NameError: global name 'EMAIL_PW' is not defined
2014-03-17 17:47:58,764 [ERROR] django.request: Internal Server Error: /
Traceback (most recent call last):
  File "/usr/local/lib/python2.7/dist-packages/django/core/handlers/base.py", line 114, in get_response
    response = wrapped_callback(request, *callback_args, **callback_kwargs)
  File "/home/gk/django_test/django_test/views.py", line 17, in index
    logr.debug(MAIL_HOST_PASSWORD)
NameError: global name 'MAIL_HOST_PASSWORD' is not defined
2014-03-17 17:48:13,173 [ERROR] django.request: Internal Server Error: /
Traceback (most recent call last):
  File "/usr/local/lib/python2.7/dist-packages/django/core/handlers/base.py", line 114, in get_response
    response = wrapped_callback(request, *callback_args, **callback_kwargs)
  File "/home/gk/django_test/django_test/views.py", line 17, in index
    logr.debug(EMAIL_HOST_PASSWORD)
NameError: global name 'EMAIL_HOST_PASSWORD' is not defined
2014-03-17 17:48:48,473 [ERROR] django.request: Internal Server Error: /
Traceback (most recent call last):
  File "/usr/local/lib/python2.7/dist-packages/django/core/handlers/base.py", line 114, in get_response
    response = wrapped_callback(request, *callback_args, **callback_kwargs)
  File "/home/gk/django_test/django_test/views.py", line 17, in index
    logr.debug(EMAIL_HOST_PASSWORD)
NameError: global name 'EMAIL_HOST_PASSWORD' is not defined
2014-03-17 17:51:23,547 [ERROR] django.request: Internal Server Error: /
Traceback (most recent call last):
  File "/usr/local/lib/python2.7/dist-packages/django/core/handlers/base.py", line 114, in get_response
    response = wrapped_callback(request, *callback_args, **callback_kwargs)
  File "/home/gk/django_test/django_test/views.py", line 19, in index
    logr.debug(EMAIL_HOST_PASSWORD)
NameError: global name 'EMAIL_HOST_PASSWORD' is not defined
2014-03-17 17:52:52,950 [ERROR] django.request: Internal Server Error: /contact/
Traceback (most recent call last):
  File "/usr/local/lib/python2.7/dist-packages/django/core/handlers/base.py", line 114, in get_response
    response = wrapped_callback(request, *callback_args, **callback_kwargs)
  File "/usr/local/lib/python2.7/dist-packages/django/views/generic/base.py", line 69, in view
    return self.dispatch(request, *args, **kwargs)
  File "/usr/local/lib/python2.7/dist-packages/django/contrib/formtools/wizard/views.py", line 236, in dispatch
    response = super(WizardView, self).dispatch(request, *args, **kwargs)
  File "/usr/local/lib/python2.7/dist-packages/django/views/generic/base.py", line 87, in dispatch
    return handler(request, *args, **kwargs)
  File "/usr/local/lib/python2.7/dist-packages/django/contrib/formtools/wizard/views.py", line 297, in post
    return self.render_done(form, **kwargs)
  File "/usr/local/lib/python2.7/dist-packages/django/contrib/formtools/wizard/views.py", line 350, in render_done
    done_response = self.done(final_form_list, **kwargs)
  File "/home/gk/django_test/django_test/views.py", line 88, in done
  File "/usr/local/lib/python2.7/dist-packages/django/shortcuts/__init__.py", line 29, in render_to_response
    return HttpResponse(loader.render_to_string(*args, **kwargs), **httpresponse_kwargs)
  File "/usr/local/lib/python2.7/dist-packages/django/template/loader.py", line 162, in render_to_string
    t = get_template(template_name)
  File "/usr/local/lib/python2.7/dist-packages/django/template/loader.py", line 138, in get_template
    template, origin = find_template(template_name)
  File "/usr/local/lib/python2.7/dist-packages/django/template/loader.py", line 127, in find_template
    source, display_name = loader(name, dirs)
  File "/usr/local/lib/python2.7/dist-packages/django/template/loader.py", line 43, in __call__
    return self.load_template(template_name, template_dirs)
  File "/usr/local/lib/python2.7/dist-packages/django/template/loader.py", line 49, in load_template
    template = get_template_from_string(source, origin, template_name)
  File "/usr/local/lib/python2.7/dist-packages/django/template/loader.py", line 149, in get_template_from_string
    return Template(source, origin, name)
  File "/usr/local/lib/python2.7/dist-packages/django/template/base.py", line 125, in __init__
    self.nodelist = compile_string(template_string, origin)
  File "/usr/local/lib/python2.7/dist-packages/django/template/base.py", line 153, in compile_string
    return parser.parse()
  File "/usr/local/lib/python2.7/dist-packages/django/template/base.py", line 276, in parse
    self.invalid_block_tag(token, command, parse_until)
  File "/usr/local/lib/python2.7/dist-packages/django/template/base.py", line 332, in invalid_block_tag
    raise self.error(token, "Invalid block tag: '%s'" % command)
TemplateSyntaxError: Invalid block tag: 'extands'
